ERROR:root:Error for link http://key74.ru/certenroll/!0423!0426%20!041a!043b!044e!0447-!041b.crl
Traceback (most recent call last):
  File "C:\Users\a.karpihin\PycharmProjects\xml_perser\main.py", line 45, in <module>
    urlreq.urlretrieve(url_link.text, 'C:/Users/a.karpihin/Desktop/certs/отозванные/' + new_name + '.crl')
  File "C:\Users\a.karpihin\AppData\Local\Programs\Python\Python39\lib\urllib\request.py", line 239, in urlretrieve
    with contextlib.closing(urlopen(url, data)) as fp:
  File "C:\Users\a.karpihin\AppData\Local\Programs\Python\Python39\lib\urllib\request.py", line 214, in urlopen
    return opener.open(url, data, timeout)
  File "C:\Users\a.karpihin\AppData\Local\Programs\Python\Python39\lib\urllib\request.py", line 523, in open
    response = meth(req, response)
  File "C:\Users\a.karpihin\AppData\Local\Programs\Python\Python39\lib\urllib\request.py", line 632, in http_response
    response = self.parent.error(
  File "C:\Users\a.karpihin\AppData\Local\Programs\Python\Python39\lib\urllib\request.py", line 561, in error
    return self._call_chain(*args)
  File "C:\Users\a.karpihin\AppData\Local\Programs\Python\Python39\lib\urllib\request.py", line 494, in _call_chain
    result = func(*args)
  File "C:\Users\a.karpihin\AppData\Local\Programs\Python\Python39\lib\urllib\request.py", line 641, in http_error_default
    raise HTTPError(req.full_url, code, msg, hdrs, fp)
urllib.error.HTTPError: HTTP Error 404: Not Found
ERROR:root:Error for link http://www.security.ru/ca/mo_accredited_2015.crl
Traceback (most recent call last):
  File "C:\Users\a.karpihin\PycharmProjects\xml_perser\main.py", line 45, in <module>
    urlreq.urlretrieve(url_link.text, 'C:/Users/a.karpihin/Desktop/certs/отозванные/' + new_name + '.crl')
  File "C:\Users\a.karpihin\AppData\Local\Programs\Python\Python39\lib\urllib\request.py", line 239, in urlretrieve
    with contextlib.closing(urlopen(url, data)) as fp:
  File "C:\Users\a.karpihin\AppData\Local\Programs\Python\Python39\lib\urllib\request.py", line 214, in urlopen
    return opener.open(url, data, timeout)
  File "C:\Users\a.karpihin\AppData\Local\Programs\Python\Python39\lib\urllib\request.py", line 523, in open
    response = meth(req, response)
  File "C:\Users\a.karpihin\AppData\Local\Programs\Python\Python39\lib\urllib\request.py", line 632, in http_response
    response = self.parent.error(
  File "C:\Users\a.karpihin\AppData\Local\Programs\Python\Python39\lib\urllib\request.py", line 555, in error
    result = self._call_chain(*args)
  File "C:\Users\a.karpihin\AppData\Local\Programs\Python\Python39\lib\urllib\request.py", line 494, in _call_chain
    result = func(*args)
  File "C:\Users\a.karpihin\AppData\Local\Programs\Python\Python39\lib\urllib\request.py", line 747, in http_error_302
    return self.parent.open(new, timeout=req.timeout)
  File "C:\Users\a.karpihin\AppData\Local\Programs\Python\Python39\lib\urllib\request.py", line 523, in open
    response = meth(req, response)
  File "C:\Users\a.karpihin\AppData\Local\Programs\Python\Python39\lib\urllib\request.py", line 632, in http_response
    response = self.parent.error(
  File "C:\Users\a.karpihin\AppData\Local\Programs\Python\Python39\lib\urllib\request.py", line 561, in error
    return self._call_chain(*args)
  File "C:\Users\a.karpihin\AppData\Local\Programs\Python\Python39\lib\urllib\request.py", line 494, in _call_chain
    result = func(*args)
  File "C:\Users\a.karpihin\AppData\Local\Programs\Python\Python39\lib\urllib\request.py", line 641, in http_error_default
    raise HTTPError(req.full_url, code, msg, hdrs, fp)
urllib.error.HTTPError: HTTP Error 404: Not Found
ERROR:root:Error for link http://ca1.rtsec.ru/cdp/cba1-2012.crl
Traceback (most recent call last):
  File "C:\Users\a.karpihin\AppData\Local\Programs\Python\Python39\lib\urllib\request.py", line 1346, in do_open
    h.request(req.get_method(), req.selector, req.data, headers,
  File "C:\Users\a.karpihin\AppData\Local\Programs\Python\Python39\lib\http\client.py", line 1253, in request
    self._send_request(method, url, body, headers, encode_chunked)
  File "C:\Users\a.karpihin\AppData\Local\Programs\Python\Python39\lib\http\client.py", line 1299, in _send_request
    self.endheaders(body, encode_chunked=encode_chunked)
  File "C:\Users\a.karpihin\AppData\Local\Programs\Python\Python39\lib\http\client.py", line 1248, in endheaders
    self._send_output(message_body, encode_chunked=encode_chunked)
  File "C:\Users\a.karpihin\AppData\Local\Programs\Python\Python39\lib\http\client.py", line 1008, in _send_output
    self.send(msg)
  File "C:\Users\a.karpihin\AppData\Local\Programs\Python\Python39\lib\http\client.py", line 948, in send
    self.connect()
  File "C:\Users\a.karpihin\AppData\Local\Programs\Python\Python39\lib\http\client.py", line 919, in connect
    self.sock = self._create_connection(
  File "C:\Users\a.karpihin\AppData\Local\Programs\Python\Python39\lib\socket.py", line 822, in create_connection
    for res in getaddrinfo(host, port, 0, SOCK_STREAM):
  File "C:\Users\a.karpihin\AppData\Local\Programs\Python\Python39\lib\socket.py", line 953, in getaddrinfo
    for res in _socket.getaddrinfo(host, port, family, type, proto, flags):
socket.gaierror: [Errno 11001] getaddrinfo failed

During handling of the above exception, another exception occurred:

Traceback (most recent call last):
  File "C:\Users\a.karpihin\PycharmProjects\xml_perser\main.py", line 45, in <module>
    urlreq.urlretrieve(url_link.text, 'C:/Users/a.karpihin/Desktop/certs/отозванные/' + new_name + '.crl')
  File "C:\Users\a.karpihin\AppData\Local\Programs\Python\Python39\lib\urllib\request.py", line 239, in urlretrieve
    with contextlib.closing(urlopen(url, data)) as fp:
  File "C:\Users\a.karpihin\AppData\Local\Programs\Python\Python39\lib\urllib\request.py", line 214, in urlopen
    return opener.open(url, data, timeout)
  File "C:\Users\a.karpihin\AppData\Local\Programs\Python\Python39\lib\urllib\request.py", line 517, in open
    response = self._open(req, data)
  File "C:\Users\a.karpihin\AppData\Local\Programs\Python\Python39\lib\urllib\request.py", line 534, in _open
    result = self._call_chain(self.handle_open, protocol, protocol +
  File "C:\Users\a.karpihin\AppData\Local\Programs\Python\Python39\lib\urllib\request.py", line 494, in _call_chain
    result = func(*args)
  File "C:\Users\a.karpihin\AppData\Local\Programs\Python\Python39\lib\urllib\request.py", line 1375, in http_open
    return self.do_open(http.client.HTTPConnection, req)
  File "C:\Users\a.karpihin\AppData\Local\Programs\Python\Python39\lib\urllib\request.py", line 1349, in do_open
    raise URLError(err)
urllib.error.URLError: <urlopen error [Errno 11001] getaddrinfo failed>
ERROR:root:Error for link http://ca.nebopro.ru/revoked_2016.crl
Traceback (most recent call last):
  File "C:\Users\a.karpihin\AppData\Local\Programs\Python\Python39\lib\urllib\request.py", line 1346, in do_open
    h.request(req.get_method(), req.selector, req.data, headers,
  File "C:\Users\a.karpihin\AppData\Local\Programs\Python\Python39\lib\http\client.py", line 1253, in request
    self._send_request(method, url, body, headers, encode_chunked)
  File "C:\Users\a.karpihin\AppData\Local\Programs\Python\Python39\lib\http\client.py", line 1299, in _send_request
    self.endheaders(body, encode_chunked=encode_chunked)
  File "C:\Users\a.karpihin\AppData\Local\Programs\Python\Python39\lib\http\client.py", line 1248, in endheaders
    self._send_output(message_body, encode_chunked=encode_chunked)
  File "C:\Users\a.karpihin\AppData\Local\Programs\Python\Python39\lib\http\client.py", line 1008, in _send_output
    self.send(msg)
  File "C:\Users\a.karpihin\AppData\Local\Programs\Python\Python39\lib\http\client.py", line 948, in send
    self.connect()
  File "C:\Users\a.karpihin\AppData\Local\Programs\Python\Python39\lib\http\client.py", line 919, in connect
    self.sock = self._create_connection(
  File "C:\Users\a.karpihin\AppData\Local\Programs\Python\Python39\lib\socket.py", line 843, in create_connection
    raise err
  File "C:\Users\a.karpihin\AppData\Local\Programs\Python\Python39\lib\socket.py", line 831, in create_connection
    sock.connect(sa)
TimeoutError: [WinError 10060] Попытка установить соединение была безуспешной, т.к. от другого компьютера за требуемое время не получен нужный отклик, или было разорвано уже установленное соединение из-за неверного отклика уже подключенного компьютера

During handling of the above exception, another exception occurred:

Traceback (most recent call last):
  File "C:\Users\a.karpihin\PycharmProjects\xml_perser\main.py", line 45, in <module>
    urlreq.urlretrieve(url_link.text, 'C:/Users/a.karpihin/Desktop/certs/отозванные/' + new_name + '.crl')
  File "C:\Users\a.karpihin\AppData\Local\Programs\Python\Python39\lib\urllib\request.py", line 239, in urlretrieve
    with contextlib.closing(urlopen(url, data)) as fp:
  File "C:\Users\a.karpihin\AppData\Local\Programs\Python\Python39\lib\urllib\request.py", line 214, in urlopen
    return opener.open(url, data, timeout)
  File "C:\Users\a.karpihin\AppData\Local\Programs\Python\Python39\lib\urllib\request.py", line 517, in open
    response = self._open(req, data)
  File "C:\Users\a.karpihin\AppData\Local\Programs\Python\Python39\lib\urllib\request.py", line 534, in _open
    result = self._call_chain(self.handle_open, protocol, protocol +
  File "C:\Users\a.karpihin\AppData\Local\Programs\Python\Python39\lib\urllib\request.py", line 494, in _call_chain
    result = func(*args)
  File "C:\Users\a.karpihin\AppData\Local\Programs\Python\Python39\lib\urllib\request.py", line 1375, in http_open
    return self.do_open(http.client.HTTPConnection, req)
  File "C:\Users\a.karpihin\AppData\Local\Programs\Python\Python39\lib\urllib\request.py", line 1349, in do_open
    raise URLError(err)
urllib.error.URLError: <urlopen error [WinError 10060] Попытка установить соединение была безуспешной, т.к. от другого компьютера за требуемое время не получен нужный отклик, или было разорвано уже установленное соединение из-за неверного отклика уже подключенного компьютера>
ERROR:root:Error for link http://ca2.ifru.ru/ra/cdp/5cc88605768c98be30f19f78d5827985f19ca9b4.crl
Traceback (most recent call last):
  File "C:\Users\a.karpihin\PycharmProjects\xml_perser\main.py", line 45, in <module>
    urlreq.urlretrieve(url_link.text, 'C:/Users/a.karpihin/Desktop/certs/отозванные/' + new_name + '.crl')
  File "C:\Users\a.karpihin\AppData\Local\Programs\Python\Python39\lib\urllib\request.py", line 239, in urlretrieve
    with contextlib.closing(urlopen(url, data)) as fp:
  File "C:\Users\a.karpihin\AppData\Local\Programs\Python\Python39\lib\urllib\request.py", line 214, in urlopen
    return opener.open(url, data, timeout)
  File "C:\Users\a.karpihin\AppData\Local\Programs\Python\Python39\lib\urllib\request.py", line 523, in open
    response = meth(req, response)
  File "C:\Users\a.karpihin\AppData\Local\Programs\Python\Python39\lib\urllib\request.py", line 632, in http_response
    response = self.parent.error(
  File "C:\Users\a.karpihin\AppData\Local\Programs\Python\Python39\lib\urllib\request.py", line 561, in error
    return self._call_chain(*args)
  File "C:\Users\a.karpihin\AppData\Local\Programs\Python\Python39\lib\urllib\request.py", line 494, in _call_chain
    result = func(*args)
  File "C:\Users\a.karpihin\AppData\Local\Programs\Python\Python39\lib\urllib\request.py", line 641, in http_error_default
    raise HTTPError(req.full_url, code, msg, hdrs, fp)
urllib.error.HTTPError: HTTP Error 404: Not Found
ERROR:root:Error for link http://ladogatele.com/docs/otozvannye_sertificaty_ladogatelecom.crl
Traceback (most recent call last):
  File "C:\Users\a.karpihin\PycharmProjects\xml_perser\main.py", line 45, in <module>
    urlreq.urlretrieve(url_link.text, 'C:/Users/a.karpihin/Desktop/certs/отозванные/' + new_name + '.crl')
  File "C:\Users\a.karpihin\AppData\Local\Programs\Python\Python39\lib\urllib\request.py", line 239, in urlretrieve
    with contextlib.closing(urlopen(url, data)) as fp:
  File "C:\Users\a.karpihin\AppData\Local\Programs\Python\Python39\lib\urllib\request.py", line 214, in urlopen
    return opener.open(url, data, timeout)
  File "C:\Users\a.karpihin\AppData\Local\Programs\Python\Python39\lib\urllib\request.py", line 523, in open
    response = meth(req, response)
  File "C:\Users\a.karpihin\AppData\Local\Programs\Python\Python39\lib\urllib\request.py", line 632, in http_response
    response = self.parent.error(
  File "C:\Users\a.karpihin\AppData\Local\Programs\Python\Python39\lib\urllib\request.py", line 561, in error
    return self._call_chain(*args)
  File "C:\Users\a.karpihin\AppData\Local\Programs\Python\Python39\lib\urllib\request.py", line 494, in _call_chain
    result = func(*args)
  File "C:\Users\a.karpihin\AppData\Local\Programs\Python\Python39\lib\urllib\request.py", line 641, in http_error_default
    raise HTTPError(req.full_url, code, msg, hdrs, fp)
urllib.error.HTTPError: HTTP Error 503: Service Temporarily Unavailable
ERROR:root:Error for link http://kurgan-med.ru/fbase/uc/gbumiac.crl
Traceback (most recent call last):
  File "C:\Users\a.karpihin\PycharmProjects\xml_perser\main.py", line 45, in <module>
    urlreq.urlretrieve(url_link.text, 'C:/Users/a.karpihin/Desktop/certs/отозванные/' + new_name + '.crl')
  File "C:\Users\a.karpihin\AppData\Local\Programs\Python\Python39\lib\urllib\request.py", line 239, in urlretrieve
    with contextlib.closing(urlopen(url, data)) as fp:
  File "C:\Users\a.karpihin\AppData\Local\Programs\Python\Python39\lib\urllib\request.py", line 214, in urlopen
    return opener.open(url, data, timeout)
  File "C:\Users\a.karpihin\AppData\Local\Programs\Python\Python39\lib\urllib\request.py", line 523, in open
    response = meth(req, response)
  File "C:\Users\a.karpihin\AppData\Local\Programs\Python\Python39\lib\urllib\request.py", line 632, in http_response
    response = self.parent.error(
  File "C:\Users\a.karpihin\AppData\Local\Programs\Python\Python39\lib\urllib\request.py", line 555, in error
    result = self._call_chain(*args)
  File "C:\Users\a.karpihin\AppData\Local\Programs\Python\Python39\lib\urllib\request.py", line 494, in _call_chain
    result = func(*args)
  File "C:\Users\a.karpihin\AppData\Local\Programs\Python\Python39\lib\urllib\request.py", line 747, in http_error_302
    return self.parent.open(new, timeout=req.timeout)
  File "C:\Users\a.karpihin\AppData\Local\Programs\Python\Python39\lib\urllib\request.py", line 523, in open
    response = meth(req, response)
  File "C:\Users\a.karpihin\AppData\Local\Programs\Python\Python39\lib\urllib\request.py", line 632, in http_response
    response = self.parent.error(
  File "C:\Users\a.karpihin\AppData\Local\Programs\Python\Python39\lib\urllib\request.py", line 561, in error
    return self._call_chain(*args)
  File "C:\Users\a.karpihin\AppData\Local\Programs\Python\Python39\lib\urllib\request.py", line 494, in _call_chain
    result = func(*args)
  File "C:\Users\a.karpihin\AppData\Local\Programs\Python\Python39\lib\urllib\request.py", line 641, in http_error_default
    raise HTTPError(req.full_url, code, msg, hdrs, fp)
urllib.error.HTTPError: HTTP Error 404: Not Found
ERROR:root:Error for link https://cbinfo.ru/files/10537-kid2283414DF6F1A88436326E54E7BF657D6C9EAD4B/revokedCerts.crl
Traceback (most recent call last):
  File "C:\Users\a.karpihin\AppData\Local\Programs\Python\Python39\lib\urllib\request.py", line 1346, in do_open
    h.request(req.get_method(), req.selector, req.data, headers,
  File "C:\Users\a.karpihin\AppData\Local\Programs\Python\Python39\lib\http\client.py", line 1253, in request
    self._send_request(method, url, body, headers, encode_chunked)
  File "C:\Users\a.karpihin\AppData\Local\Programs\Python\Python39\lib\http\client.py", line 1299, in _send_request
    self.endheaders(body, encode_chunked=encode_chunked)
  File "C:\Users\a.karpihin\AppData\Local\Programs\Python\Python39\lib\http\client.py", line 1248, in endheaders
    self._send_output(message_body, encode_chunked=encode_chunked)
  File "C:\Users\a.karpihin\AppData\Local\Programs\Python\Python39\lib\http\client.py", line 1008, in _send_output
    self.send(msg)
  File "C:\Users\a.karpihin\AppData\Local\Programs\Python\Python39\lib\http\client.py", line 948, in send
    self.connect()
  File "C:\Users\a.karpihin\AppData\Local\Programs\Python\Python39\lib\http\client.py", line 1415, in connect
    super().connect()
  File "C:\Users\a.karpihin\AppData\Local\Programs\Python\Python39\lib\http\client.py", line 919, in connect
    self.sock = self._create_connection(
  File "C:\Users\a.karpihin\AppData\Local\Programs\Python\Python39\lib\socket.py", line 822, in create_connection
    for res in getaddrinfo(host, port, 0, SOCK_STREAM):
  File "C:\Users\a.karpihin\AppData\Local\Programs\Python\Python39\lib\socket.py", line 953, in getaddrinfo
    for res in _socket.getaddrinfo(host, port, family, type, proto, flags):
socket.gaierror: [Errno 11001] getaddrinfo failed

During handling of the above exception, another exception occurred:

Traceback (most recent call last):
  File "C:\Users\a.karpihin\PycharmProjects\xml_perser\main.py", line 45, in <module>
    urlreq.urlretrieve(url_link.text, 'C:/Users/a.karpihin/Desktop/certs/отозванные/' + new_name + '.crl')
  File "C:\Users\a.karpihin\AppData\Local\Programs\Python\Python39\lib\urllib\request.py", line 239, in urlretrieve
    with contextlib.closing(urlopen(url, data)) as fp:
  File "C:\Users\a.karpihin\AppData\Local\Programs\Python\Python39\lib\urllib\request.py", line 214, in urlopen
    return opener.open(url, data, timeout)
  File "C:\Users\a.karpihin\AppData\Local\Programs\Python\Python39\lib\urllib\request.py", line 517, in open
    response = self._open(req, data)
  File "C:\Users\a.karpihin\AppData\Local\Programs\Python\Python39\lib\urllib\request.py", line 534, in _open
    result = self._call_chain(self.handle_open, protocol, protocol +
  File "C:\Users\a.karpihin\AppData\Local\Programs\Python\Python39\lib\urllib\request.py", line 494, in _call_chain
    result = func(*args)
  File "C:\Users\a.karpihin\AppData\Local\Programs\Python\Python39\lib\urllib\request.py", line 1389, in https_open
    return self.do_open(http.client.HTTPSConnection, req,
  File "C:\Users\a.karpihin\AppData\Local\Programs\Python\Python39\lib\urllib\request.py", line 1349, in do_open
    raise URLError(err)
urllib.error.URLError: <urlopen error [Errno 11001] getaddrinfo failed>
ERROR:root:Error for link http://ca2.prominn.ru/ca/86cb86d5c99c7fd16f0b1b71eb9bdfdba4fb91ab.crl
Traceback (most recent call last):
  File "C:\Users\a.karpihin\AppData\Local\Programs\Python\Python39\lib\urllib\request.py", line 1346, in do_open
    h.request(req.get_method(), req.selector, req.data, headers,
  File "C:\Users\a.karpihin\AppData\Local\Programs\Python\Python39\lib\http\client.py", line 1253, in request
    self._send_request(method, url, body, headers, encode_chunked)
  File "C:\Users\a.karpihin\AppData\Local\Programs\Python\Python39\lib\http\client.py", line 1299, in _send_request
    self.endheaders(body, encode_chunked=encode_chunked)
  File "C:\Users\a.karpihin\AppData\Local\Programs\Python\Python39\lib\http\client.py", line 1248, in endheaders
    self._send_output(message_body, encode_chunked=encode_chunked)
  File "C:\Users\a.karpihin\AppData\Local\Programs\Python\Python39\lib\http\client.py", line 1008, in _send_output
    self.send(msg)
  File "C:\Users\a.karpihin\AppData\Local\Programs\Python\Python39\lib\http\client.py", line 948, in send
    self.connect()
  File "C:\Users\a.karpihin\AppData\Local\Programs\Python\Python39\lib\http\client.py", line 919, in connect
    self.sock = self._create_connection(
  File "C:\Users\a.karpihin\AppData\Local\Programs\Python\Python39\lib\socket.py", line 822, in create_connection
    for res in getaddrinfo(host, port, 0, SOCK_STREAM):
  File "C:\Users\a.karpihin\AppData\Local\Programs\Python\Python39\lib\socket.py", line 953, in getaddrinfo
    for res in _socket.getaddrinfo(host, port, family, type, proto, flags):
socket.gaierror: [Errno 11001] getaddrinfo failed

During handling of the above exception, another exception occurred:

Traceback (most recent call last):
  File "C:\Users\a.karpihin\PycharmProjects\xml_perser\main.py", line 45, in <module>
    urlreq.urlretrieve(url_link.text, 'C:/Users/a.karpihin/Desktop/certs/отозванные/' + new_name + '.crl')
  File "C:\Users\a.karpihin\AppData\Local\Programs\Python\Python39\lib\urllib\request.py", line 239, in urlretrieve
    with contextlib.closing(urlopen(url, data)) as fp:
  File "C:\Users\a.karpihin\AppData\Local\Programs\Python\Python39\lib\urllib\request.py", line 214, in urlopen
    return opener.open(url, data, timeout)
  File "C:\Users\a.karpihin\AppData\Local\Programs\Python\Python39\lib\urllib\request.py", line 517, in open
    response = self._open(req, data)
  File "C:\Users\a.karpihin\AppData\Local\Programs\Python\Python39\lib\urllib\request.py", line 534, in _open
    result = self._call_chain(self.handle_open, protocol, protocol +
  File "C:\Users\a.karpihin\AppData\Local\Programs\Python\Python39\lib\urllib\request.py", line 494, in _call_chain
    result = func(*args)
  File "C:\Users\a.karpihin\AppData\Local\Programs\Python\Python39\lib\urllib\request.py", line 1375, in http_open
    return self.do_open(http.client.HTTPConnection, req)
  File "C:\Users\a.karpihin\AppData\Local\Programs\Python\Python39\lib\urllib\request.py", line 1349, in do_open
    raise URLError(err)
urllib.error.URLError: <urlopen error [Errno 11001] getaddrinfo failed>
ERROR:root:Error for link http://ucvtb24.ru/CA.crl
Traceback (most recent call last):
  File "C:\Users\a.karpihin\AppData\Local\Programs\Python\Python39\lib\urllib\request.py", line 1346, in do_open
    h.request(req.get_method(), req.selector, req.data, headers,
  File "C:\Users\a.karpihin\AppData\Local\Programs\Python\Python39\lib\http\client.py", line 1253, in request
    self._send_request(method, url, body, headers, encode_chunked)
  File "C:\Users\a.karpihin\AppData\Local\Programs\Python\Python39\lib\http\client.py", line 1299, in _send_request
    self.endheaders(body, encode_chunked=encode_chunked)
  File "C:\Users\a.karpihin\AppData\Local\Programs\Python\Python39\lib\http\client.py", line 1248, in endheaders
    self._send_output(message_body, encode_chunked=encode_chunked)
  File "C:\Users\a.karpihin\AppData\Local\Programs\Python\Python39\lib\http\client.py", line 1008, in _send_output
    self.send(msg)
  File "C:\Users\a.karpihin\AppData\Local\Programs\Python\Python39\lib\http\client.py", line 948, in send
    self.connect()
  File "C:\Users\a.karpihin\AppData\Local\Programs\Python\Python39\lib\http\client.py", line 919, in connect
    self.sock = self._create_connection(
  File "C:\Users\a.karpihin\AppData\Local\Programs\Python\Python39\lib\socket.py", line 843, in create_connection
    raise err
  File "C:\Users\a.karpihin\AppData\Local\Programs\Python\Python39\lib\socket.py", line 831, in create_connection
    sock.connect(sa)
TimeoutError: [WinError 10060] Попытка установить соединение была безуспешной, т.к. от другого компьютера за требуемое время не получен нужный отклик, или было разорвано уже установленное соединение из-за неверного отклика уже подключенного компьютера

During handling of the above exception, another exception occurred:

Traceback (most recent call last):
  File "C:\Users\a.karpihin\PycharmProjects\xml_perser\main.py", line 45, in <module>
    urlreq.urlretrieve(url_link.text, 'C:/Users/a.karpihin/Desktop/certs/отозванные/' + new_name + '.crl')
  File "C:\Users\a.karpihin\AppData\Local\Programs\Python\Python39\lib\urllib\request.py", line 239, in urlretrieve
    with contextlib.closing(urlopen(url, data)) as fp:
  File "C:\Users\a.karpihin\AppData\Local\Programs\Python\Python39\lib\urllib\request.py", line 214, in urlopen
    return opener.open(url, data, timeout)
  File "C:\Users\a.karpihin\AppData\Local\Programs\Python\Python39\lib\urllib\request.py", line 517, in open
    response = self._open(req, data)
  File "C:\Users\a.karpihin\AppData\Local\Programs\Python\Python39\lib\urllib\request.py", line 534, in _open
    result = self._call_chain(self.handle_open, protocol, protocol +
  File "C:\Users\a.karpihin\AppData\Local\Programs\Python\Python39\lib\urllib\request.py", line 494, in _call_chain
    result = func(*args)
  File "C:\Users\a.karpihin\AppData\Local\Programs\Python\Python39\lib\urllib\request.py", line 1375, in http_open
    return self.do_open(http.client.HTTPConnection, req)
  File "C:\Users\a.karpihin\AppData\Local\Programs\Python\Python39\lib\urllib\request.py", line 1349, in do_open
    raise URLError(err)
urllib.error.URLError: <urlopen error [WinError 10060] Попытка установить соединение была безуспешной, т.к. от другого компьютера за требуемое время не получен нужный отклик, или было разорвано уже установленное соединение из-за неверного отклика уже подключенного компьютера>
ERROR:root:Error for link http://pki.kami.ru/repository/CRL/kamica.crl
Traceback (most recent call last):
  File "C:\Users\a.karpihin\AppData\Local\Programs\Python\Python39\lib\urllib\request.py", line 1346, in do_open
    h.request(req.get_method(), req.selector, req.data, headers,
  File "C:\Users\a.karpihin\AppData\Local\Programs\Python\Python39\lib\http\client.py", line 1253, in request
    self._send_request(method, url, body, headers, encode_chunked)
  File "C:\Users\a.karpihin\AppData\Local\Programs\Python\Python39\lib\http\client.py", line 1299, in _send_request
    self.endheaders(body, encode_chunked=encode_chunked)
  File "C:\Users\a.karpihin\AppData\Local\Programs\Python\Python39\lib\http\client.py", line 1248, in endheaders
    self._send_output(message_body, encode_chunked=encode_chunked)
  File "C:\Users\a.karpihin\AppData\Local\Programs\Python\Python39\lib\http\client.py", line 1008, in _send_output
    self.send(msg)
  File "C:\Users\a.karpihin\AppData\Local\Programs\Python\Python39\lib\http\client.py", line 948, in send
    self.connect()
  File "C:\Users\a.karpihin\AppData\Local\Programs\Python\Python39\lib\http\client.py", line 919, in connect
    self.sock = self._create_connection(
  File "C:\Users\a.karpihin\AppData\Local\Programs\Python\Python39\lib\socket.py", line 843, in create_connection
    raise err
  File "C:\Users\a.karpihin\AppData\Local\Programs\Python\Python39\lib\socket.py", line 831, in create_connection
    sock.connect(sa)
TimeoutError: [WinError 10060] Попытка установить соединение была безуспешной, т.к. от другого компьютера за требуемое время не получен нужный отклик, или было разорвано уже установленное соединение из-за неверного отклика уже подключенного компьютера

During handling of the above exception, another exception occurred:

Traceback (most recent call last):
  File "C:\Users\a.karpihin\PycharmProjects\xml_perser\main.py", line 45, in <module>
    urlreq.urlretrieve(url_link.text, 'C:/Users/a.karpihin/Desktop/certs/отозванные/' + new_name + '.crl')
  File "C:\Users\a.karpihin\AppData\Local\Programs\Python\Python39\lib\urllib\request.py", line 239, in urlretrieve
    with contextlib.closing(urlopen(url, data)) as fp:
  File "C:\Users\a.karpihin\AppData\Local\Programs\Python\Python39\lib\urllib\request.py", line 214, in urlopen
    return opener.open(url, data, timeout)
  File "C:\Users\a.karpihin\AppData\Local\Programs\Python\Python39\lib\urllib\request.py", line 517, in open
    response = self._open(req, data)
  File "C:\Users\a.karpihin\AppData\Local\Programs\Python\Python39\lib\urllib\request.py", line 534, in _open
    result = self._call_chain(self.handle_open, protocol, protocol +
  File "C:\Users\a.karpihin\AppData\Local\Programs\Python\Python39\lib\urllib\request.py", line 494, in _call_chain
    result = func(*args)
  File "C:\Users\a.karpihin\AppData\Local\Programs\Python\Python39\lib\urllib\request.py", line 1375, in http_open
    return self.do_open(http.client.HTTPConnection, req)
  File "C:\Users\a.karpihin\AppData\Local\Programs\Python\Python39\lib\urllib\request.py", line 1349, in do_open
    raise URLError(err)
urllib.error.URLError: <urlopen error [WinError 10060] Попытка установить соединение была безуспешной, т.к. от другого компьютера за требуемое время не получен нужный отклик, или было разорвано уже установленное соединение из-за неверного отклика уже подключенного компьютера>
ERROR:root:Error for link http://www.tvercrypto.ru/cdp/cfe5067aa1bda3f2e168432a875489650517652b.crl
Traceback (most recent call last):
  File "C:\Users\a.karpihin\PycharmProjects\xml_perser\main.py", line 45, in <module>
    urlreq.urlretrieve(url_link.text, 'C:/Users/a.karpihin/Desktop/certs/отозванные/' + new_name + '.crl')
  File "C:\Users\a.karpihin\AppData\Local\Programs\Python\Python39\lib\urllib\request.py", line 239, in urlretrieve
    with contextlib.closing(urlopen(url, data)) as fp:
  File "C:\Users\a.karpihin\AppData\Local\Programs\Python\Python39\lib\urllib\request.py", line 214, in urlopen
    return opener.open(url, data, timeout)
  File "C:\Users\a.karpihin\AppData\Local\Programs\Python\Python39\lib\urllib\request.py", line 523, in open
    response = meth(req, response)
  File "C:\Users\a.karpihin\AppData\Local\Programs\Python\Python39\lib\urllib\request.py", line 632, in http_response
    response = self.parent.error(
  File "C:\Users\a.karpihin\AppData\Local\Programs\Python\Python39\lib\urllib\request.py", line 561, in error
    return self._call_chain(*args)
  File "C:\Users\a.karpihin\AppData\Local\Programs\Python\Python39\lib\urllib\request.py", line 494, in _call_chain
    result = func(*args)
  File "C:\Users\a.karpihin\AppData\Local\Programs\Python\Python39\lib\urllib\request.py", line 641, in http_error_default
    raise HTTPError(req.full_url, code, msg, hdrs, fp)
urllib.error.HTTPError: HTTP Error 404: Not Found
ERROR:root:Error for link http://uc.credos.ru/docs/credos-2015.crl
Traceback (most recent call last):
  File "C:\Users\a.karpihin\PycharmProjects\xml_perser\main.py", line 45, in <module>
    urlreq.urlretrieve(url_link.text, 'C:/Users/a.karpihin/Desktop/certs/отозванные/' + new_name + '.crl')
  File "C:\Users\a.karpihin\AppData\Local\Programs\Python\Python39\lib\urllib\request.py", line 239, in urlretrieve
    with contextlib.closing(urlopen(url, data)) as fp:
  File "C:\Users\a.karpihin\AppData\Local\Programs\Python\Python39\lib\urllib\request.py", line 214, in urlopen
    return opener.open(url, data, timeout)
  File "C:\Users\a.karpihin\AppData\Local\Programs\Python\Python39\lib\urllib\request.py", line 523, in open
    response = meth(req, response)
  File "C:\Users\a.karpihin\AppData\Local\Programs\Python\Python39\lib\urllib\request.py", line 632, in http_response
    response = self.parent.error(
  File "C:\Users\a.karpihin\AppData\Local\Programs\Python\Python39\lib\urllib\request.py", line 561, in error
    return self._call_chain(*args)
  File "C:\Users\a.karpihin\AppData\Local\Programs\Python\Python39\lib\urllib\request.py", line 494, in _call_chain
    result = func(*args)
  File "C:\Users\a.karpihin\AppData\Local\Programs\Python\Python39\lib\urllib\request.py", line 641, in http_error_default
    raise HTTPError(req.full_url, code, msg, hdrs, fp)
urllib.error.HTTPError: HTTP Error 502: Bad Gateway
ERROR:root:Error for link http://ca.krista.ru/crl/CAKristaNPO.crl
Traceback (most recent call last):
  File "C:\Users\a.karpihin\AppData\Local\Programs\Python\Python39\lib\urllib\request.py", line 1346, in do_open
    h.request(req.get_method(), req.selector, req.data, headers,
  File "C:\Users\a.karpihin\AppData\Local\Programs\Python\Python39\lib\http\client.py", line 1253, in request
    self._send_request(method, url, body, headers, encode_chunked)
  File "C:\Users\a.karpihin\AppData\Local\Programs\Python\Python39\lib\http\client.py", line 1299, in _send_request
    self.endheaders(body, encode_chunked=encode_chunked)
  File "C:\Users\a.karpihin\AppData\Local\Programs\Python\Python39\lib\http\client.py", line 1248, in endheaders
    self._send_output(message_body, encode_chunked=encode_chunked)
  File "C:\Users\a.karpihin\AppData\Local\Programs\Python\Python39\lib\http\client.py", line 1008, in _send_output
    self.send(msg)
  File "C:\Users\a.karpihin\AppData\Local\Programs\Python\Python39\lib\http\client.py", line 948, in send
    self.connect()
  File "C:\Users\a.karpihin\AppData\Local\Programs\Python\Python39\lib\http\client.py", line 919, in connect
    self.sock = self._create_connection(
  File "C:\Users\a.karpihin\AppData\Local\Programs\Python\Python39\lib\socket.py", line 843, in create_connection
    raise err
  File "C:\Users\a.karpihin\AppData\Local\Programs\Python\Python39\lib\socket.py", line 831, in create_connection
    sock.connect(sa)
TimeoutError: [WinError 10060] Попытка установить соединение была безуспешной, т.к. от другого компьютера за требуемое время не получен нужный отклик, или было разорвано уже установленное соединение из-за неверного отклика уже подключенного компьютера

During handling of the above exception, another exception occurred:

Traceback (most recent call last):
  File "C:\Users\a.karpihin\PycharmProjects\xml_perser\main.py", line 45, in <module>
    urlreq.urlretrieve(url_link.text, 'C:/Users/a.karpihin/Desktop/certs/отозванные/' + new_name + '.crl')
  File "C:\Users\a.karpihin\AppData\Local\Programs\Python\Python39\lib\urllib\request.py", line 239, in urlretrieve
    with contextlib.closing(urlopen(url, data)) as fp:
  File "C:\Users\a.karpihin\AppData\Local\Programs\Python\Python39\lib\urllib\request.py", line 214, in urlopen
    return opener.open(url, data, timeout)
  File "C:\Users\a.karpihin\AppData\Local\Programs\Python\Python39\lib\urllib\request.py", line 517, in open
    response = self._open(req, data)
  File "C:\Users\a.karpihin\AppData\Local\Programs\Python\Python39\lib\urllib\request.py", line 534, in _open
    result = self._call_chain(self.handle_open, protocol, protocol +
  File "C:\Users\a.karpihin\AppData\Local\Programs\Python\Python39\lib\urllib\request.py", line 494, in _call_chain
    result = func(*args)
  File "C:\Users\a.karpihin\AppData\Local\Programs\Python\Python39\lib\urllib\request.py", line 1375, in http_open
    return self.do_open(http.client.HTTPConnection, req)
  File "C:\Users\a.karpihin\AppData\Local\Programs\Python\Python39\lib\urllib\request.py", line 1349, in do_open
    raise URLError(err)
urllib.error.URLError: <urlopen error [WinError 10060] Попытка установить соединение была безуспешной, т.к. от другого компьютера за требуемое время не получен нужный отклик, или было разорвано уже установленное соединение из-за неверного отклика уже подключенного компьютера>
ERROR:root:Error for link http://www.czi-tver.ru/cert/czi.crl
Traceback (most recent call last):
  File "C:\Users\a.karpihin\AppData\Local\Programs\Python\Python39\lib\urllib\request.py", line 1346, in do_open
    h.request(req.get_method(), req.selector, req.data, headers,
  File "C:\Users\a.karpihin\AppData\Local\Programs\Python\Python39\lib\http\client.py", line 1253, in request
    self._send_request(method, url, body, headers, encode_chunked)
  File "C:\Users\a.karpihin\AppData\Local\Programs\Python\Python39\lib\http\client.py", line 1299, in _send_request
    self.endheaders(body, encode_chunked=encode_chunked)
  File "C:\Users\a.karpihin\AppData\Local\Programs\Python\Python39\lib\http\client.py", line 1248, in endheaders
    self._send_output(message_body, encode_chunked=encode_chunked)
  File "C:\Users\a.karpihin\AppData\Local\Programs\Python\Python39\lib\http\client.py", line 1008, in _send_output
    self.send(msg)
  File "C:\Users\a.karpihin\AppData\Local\Programs\Python\Python39\lib\http\client.py", line 948, in send
    self.connect()
  File "C:\Users\a.karpihin\AppData\Local\Programs\Python\Python39\lib\http\client.py", line 919, in connect
    self.sock = self._create_connection(
  File "C:\Users\a.karpihin\AppData\Local\Programs\Python\Python39\lib\socket.py", line 822, in create_connection
    for res in getaddrinfo(host, port, 0, SOCK_STREAM):
  File "C:\Users\a.karpihin\AppData\Local\Programs\Python\Python39\lib\socket.py", line 953, in getaddrinfo
    for res in _socket.getaddrinfo(host, port, family, type, proto, flags):
socket.gaierror: [Errno 11001] getaddrinfo failed

During handling of the above exception, another exception occurred:

Traceback (most recent call last):
  File "C:\Users\a.karpihin\PycharmProjects\xml_perser\main.py", line 45, in <module>
    urlreq.urlretrieve(url_link.text, 'C:/Users/a.karpihin/Desktop/certs/отозванные/' + new_name + '.crl')
  File "C:\Users\a.karpihin\AppData\Local\Programs\Python\Python39\lib\urllib\request.py", line 239, in urlretrieve
    with contextlib.closing(urlopen(url, data)) as fp:
  File "C:\Users\a.karpihin\AppData\Local\Programs\Python\Python39\lib\urllib\request.py", line 214, in urlopen
    return opener.open(url, data, timeout)
  File "C:\Users\a.karpihin\AppData\Local\Programs\Python\Python39\lib\urllib\request.py", line 517, in open
    response = self._open(req, data)
  File "C:\Users\a.karpihin\AppData\Local\Programs\Python\Python39\lib\urllib\request.py", line 534, in _open
    result = self._call_chain(self.handle_open, protocol, protocol +
  File "C:\Users\a.karpihin\AppData\Local\Programs\Python\Python39\lib\urllib\request.py", line 494, in _call_chain
    result = func(*args)
  File "C:\Users\a.karpihin\AppData\Local\Programs\Python\Python39\lib\urllib\request.py", line 1375, in http_open
    return self.do_open(http.client.HTTPConnection, req)
  File "C:\Users\a.karpihin\AppData\Local\Programs\Python\Python39\lib\urllib\request.py", line 1349, in do_open
    raise URLError(err)
urllib.error.URLError: <urlopen error [Errno 11001] getaddrinfo failed>
ERROR:root:Error for link http://ca.medsigroup.ru/cdp/3e5095bbe5196266eab430fc20e9acaa17ef3555.crl
Traceback (most recent call last):
  File "C:\Users\a.karpihin\AppData\Local\Programs\Python\Python39\lib\urllib\request.py", line 1346, in do_open
    h.request(req.get_method(), req.selector, req.data, headers,
  File "C:\Users\a.karpihin\AppData\Local\Programs\Python\Python39\lib\http\client.py", line 1253, in request
    self._send_request(method, url, body, headers, encode_chunked)
  File "C:\Users\a.karpihin\AppData\Local\Programs\Python\Python39\lib\http\client.py", line 1299, in _send_request
    self.endheaders(body, encode_chunked=encode_chunked)
  File "C:\Users\a.karpihin\AppData\Local\Programs\Python\Python39\lib\http\client.py", line 1248, in endheaders
    self._send_output(message_body, encode_chunked=encode_chunked)
  File "C:\Users\a.karpihin\AppData\Local\Programs\Python\Python39\lib\http\client.py", line 1008, in _send_output
    self.send(msg)
  File "C:\Users\a.karpihin\AppData\Local\Programs\Python\Python39\lib\http\client.py", line 948, in send
    self.connect()
  File "C:\Users\a.karpihin\AppData\Local\Programs\Python\Python39\lib\http\client.py", line 919, in connect
    self.sock = self._create_connection(
  File "C:\Users\a.karpihin\AppData\Local\Programs\Python\Python39\lib\socket.py", line 843, in create_connection
    raise err
  File "C:\Users\a.karpihin\AppData\Local\Programs\Python\Python39\lib\socket.py", line 831, in create_connection
    sock.connect(sa)
TimeoutError: [WinError 10060] Попытка установить соединение была безуспешной, т.к. от другого компьютера за требуемое время не получен нужный отклик, или было разорвано уже установленное соединение из-за неверного отклика уже подключенного компьютера

During handling of the above exception, another exception occurred:

Traceback (most recent call last):
  File "C:\Users\a.karpihin\PycharmProjects\xml_perser\main.py", line 45, in <module>
    urlreq.urlretrieve(url_link.text, 'C:/Users/a.karpihin/Desktop/certs/отозванные/' + new_name + '.crl')
  File "C:\Users\a.karpihin\AppData\Local\Programs\Python\Python39\lib\urllib\request.py", line 239, in urlretrieve
    with contextlib.closing(urlopen(url, data)) as fp:
  File "C:\Users\a.karpihin\AppData\Local\Programs\Python\Python39\lib\urllib\request.py", line 214, in urlopen
    return opener.open(url, data, timeout)
  File "C:\Users\a.karpihin\AppData\Local\Programs\Python\Python39\lib\urllib\request.py", line 517, in open
    response = self._open(req, data)
  File "C:\Users\a.karpihin\AppData\Local\Programs\Python\Python39\lib\urllib\request.py", line 534, in _open
    result = self._call_chain(self.handle_open, protocol, protocol +
  File "C:\Users\a.karpihin\AppData\Local\Programs\Python\Python39\lib\urllib\request.py", line 494, in _call_chain
    result = func(*args)
  File "C:\Users\a.karpihin\AppData\Local\Programs\Python\Python39\lib\urllib\request.py", line 1375, in http_open
    return self.do_open(http.client.HTTPConnection, req)
  File "C:\Users\a.karpihin\AppData\Local\Programs\Python\Python39\lib\urllib\request.py", line 1349, in do_open
    raise URLError(err)
urllib.error.URLError: <urlopen error [WinError 10060] Попытка установить соединение была безуспешной, т.к. от другого компьютера за требуемое время не получен нужный отклик, или было разорвано уже установленное соединение из-за неверного отклика уже подключенного компьютера>
ERROR:root:Error for link http://cdp2.cryptoanalitica.ru/crypto_2018.crl
Traceback (most recent call last):
  File "C:\Users\a.karpihin\AppData\Local\Programs\Python\Python39\lib\urllib\request.py", line 1346, in do_open
    h.request(req.get_method(), req.selector, req.data, headers,
  File "C:\Users\a.karpihin\AppData\Local\Programs\Python\Python39\lib\http\client.py", line 1253, in request
    self._send_request(method, url, body, headers, encode_chunked)
  File "C:\Users\a.karpihin\AppData\Local\Programs\Python\Python39\lib\http\client.py", line 1299, in _send_request
    self.endheaders(body, encode_chunked=encode_chunked)
  File "C:\Users\a.karpihin\AppData\Local\Programs\Python\Python39\lib\http\client.py", line 1248, in endheaders
    self._send_output(message_body, encode_chunked=encode_chunked)
  File "C:\Users\a.karpihin\AppData\Local\Programs\Python\Python39\lib\http\client.py", line 1008, in _send_output
    self.send(msg)
  File "C:\Users\a.karpihin\AppData\Local\Programs\Python\Python39\lib\http\client.py", line 948, in send
    self.connect()
  File "C:\Users\a.karpihin\AppData\Local\Programs\Python\Python39\lib\http\client.py", line 919, in connect
    self.sock = self._create_connection(
  File "C:\Users\a.karpihin\AppData\Local\Programs\Python\Python39\lib\socket.py", line 822, in create_connection
    for res in getaddrinfo(host, port, 0, SOCK_STREAM):
  File "C:\Users\a.karpihin\AppData\Local\Programs\Python\Python39\lib\socket.py", line 953, in getaddrinfo
    for res in _socket.getaddrinfo(host, port, family, type, proto, flags):
socket.gaierror: [Errno 11001] getaddrinfo failed

During handling of the above exception, another exception occurred:

Traceback (most recent call last):
  File "C:\Users\a.karpihin\PycharmProjects\xml_perser\main.py", line 45, in <module>
    urlreq.urlretrieve(url_link.text, 'C:/Users/a.karpihin/Desktop/certs/отозванные/' + new_name + '.crl')
  File "C:\Users\a.karpihin\AppData\Local\Programs\Python\Python39\lib\urllib\request.py", line 239, in urlretrieve
    with contextlib.closing(urlopen(url, data)) as fp:
  File "C:\Users\a.karpihin\AppData\Local\Programs\Python\Python39\lib\urllib\request.py", line 214, in urlopen
    return opener.open(url, data, timeout)
  File "C:\Users\a.karpihin\AppData\Local\Programs\Python\Python39\lib\urllib\request.py", line 517, in open
    response = self._open(req, data)
  File "C:\Users\a.karpihin\AppData\Local\Programs\Python\Python39\lib\urllib\request.py", line 534, in _open
    result = self._call_chain(self.handle_open, protocol, protocol +
  File "C:\Users\a.karpihin\AppData\Local\Programs\Python\Python39\lib\urllib\request.py", line 494, in _call_chain
    result = func(*args)
  File "C:\Users\a.karpihin\AppData\Local\Programs\Python\Python39\lib\urllib\request.py", line 1375, in http_open
    return self.do_open(http.client.HTTPConnection, req)
  File "C:\Users\a.karpihin\AppData\Local\Programs\Python\Python39\lib\urllib\request.py", line 1349, in do_open
    raise URLError(err)
urllib.error.URLError: <urlopen error [Errno 11001] getaddrinfo failed>
ERROR:root:Error for link http://uc.rosinv.ru/cdp/rti17.crl
Traceback (most recent call last):
  File "C:\Users\a.karpihin\AppData\Local\Programs\Python\Python39\lib\urllib\request.py", line 1346, in do_open
    h.request(req.get_method(), req.selector, req.data, headers,
  File "C:\Users\a.karpihin\AppData\Local\Programs\Python\Python39\lib\http\client.py", line 1253, in request
    self._send_request(method, url, body, headers, encode_chunked)
  File "C:\Users\a.karpihin\AppData\Local\Programs\Python\Python39\lib\http\client.py", line 1299, in _send_request
    self.endheaders(body, encode_chunked=encode_chunked)
  File "C:\Users\a.karpihin\AppData\Local\Programs\Python\Python39\lib\http\client.py", line 1248, in endheaders
    self._send_output(message_body, encode_chunked=encode_chunked)
  File "C:\Users\a.karpihin\AppData\Local\Programs\Python\Python39\lib\http\client.py", line 1008, in _send_output
    self.send(msg)
  File "C:\Users\a.karpihin\AppData\Local\Programs\Python\Python39\lib\http\client.py", line 948, in send
    self.connect()
  File "C:\Users\a.karpihin\AppData\Local\Programs\Python\Python39\lib\http\client.py", line 919, in connect
    self.sock = self._create_connection(
  File "C:\Users\a.karpihin\AppData\Local\Programs\Python\Python39\lib\socket.py", line 843, in create_connection
    raise err
  File "C:\Users\a.karpihin\AppData\Local\Programs\Python\Python39\lib\socket.py", line 831, in create_connection
    sock.connect(sa)
TimeoutError: [WinError 10060] Попытка установить соединение была безуспешной, т.к. от другого компьютера за требуемое время не получен нужный отклик, или было разорвано уже установленное соединение из-за неверного отклика уже подключенного компьютера

During handling of the above exception, another exception occurred:

Traceback (most recent call last):
  File "C:\Users\a.karpihin\PycharmProjects\xml_perser\main.py", line 45, in <module>
    urlreq.urlretrieve(url_link.text, 'C:/Users/a.karpihin/Desktop/certs/отозванные/' + new_name + '.crl')
  File "C:\Users\a.karpihin\AppData\Local\Programs\Python\Python39\lib\urllib\request.py", line 239, in urlretrieve
    with contextlib.closing(urlopen(url, data)) as fp:
  File "C:\Users\a.karpihin\AppData\Local\Programs\Python\Python39\lib\urllib\request.py", line 214, in urlopen
    return opener.open(url, data, timeout)
  File "C:\Users\a.karpihin\AppData\Local\Programs\Python\Python39\lib\urllib\request.py", line 517, in open
    response = self._open(req, data)
  File "C:\Users\a.karpihin\AppData\Local\Programs\Python\Python39\lib\urllib\request.py", line 534, in _open
    result = self._call_chain(self.handle_open, protocol, protocol +
  File "C:\Users\a.karpihin\AppData\Local\Programs\Python\Python39\lib\urllib\request.py", line 494, in _call_chain
    result = func(*args)
  File "C:\Users\a.karpihin\AppData\Local\Programs\Python\Python39\lib\urllib\request.py", line 1375, in http_open
    return self.do_open(http.client.HTTPConnection, req)
  File "C:\Users\a.karpihin\AppData\Local\Programs\Python\Python39\lib\urllib\request.py", line 1349, in do_open
    raise URLError(err)
urllib.error.URLError: <urlopen error [WinError 10060] Попытка установить соединение была безуспешной, т.к. от другого компьютера за требуемое время не получен нужный отклик, или было разорвано уже установленное соединение из-за неверного отклика уже подключенного компьютера>
ERROR:root:Error for link http://cdp.ifdk.com/ifdk-ca/cert.crl
Traceback (most recent call last):
  File "C:\Users\a.karpihin\AppData\Local\Programs\Python\Python39\lib\urllib\request.py", line 1346, in do_open
    h.request(req.get_method(), req.selector, req.data, headers,
  File "C:\Users\a.karpihin\AppData\Local\Programs\Python\Python39\lib\http\client.py", line 1253, in request
    self._send_request(method, url, body, headers, encode_chunked)
  File "C:\Users\a.karpihin\AppData\Local\Programs\Python\Python39\lib\http\client.py", line 1299, in _send_request
    self.endheaders(body, encode_chunked=encode_chunked)
  File "C:\Users\a.karpihin\AppData\Local\Programs\Python\Python39\lib\http\client.py", line 1248, in endheaders
    self._send_output(message_body, encode_chunked=encode_chunked)
  File "C:\Users\a.karpihin\AppData\Local\Programs\Python\Python39\lib\http\client.py", line 1008, in _send_output
    self.send(msg)
  File "C:\Users\a.karpihin\AppData\Local\Programs\Python\Python39\lib\http\client.py", line 948, in send
    self.connect()
  File "C:\Users\a.karpihin\AppData\Local\Programs\Python\Python39\lib\http\client.py", line 919, in connect
    self.sock = self._create_connection(
  File "C:\Users\a.karpihin\AppData\Local\Programs\Python\Python39\lib\socket.py", line 822, in create_connection
    for res in getaddrinfo(host, port, 0, SOCK_STREAM):
  File "C:\Users\a.karpihin\AppData\Local\Programs\Python\Python39\lib\socket.py", line 953, in getaddrinfo
    for res in _socket.getaddrinfo(host, port, family, type, proto, flags):
socket.gaierror: [Errno 11001] getaddrinfo failed

During handling of the above exception, another exception occurred:

Traceback (most recent call last):
  File "C:\Users\a.karpihin\PycharmProjects\xml_perser\main.py", line 45, in <module>
    urlreq.urlretrieve(url_link.text, 'C:/Users/a.karpihin/Desktop/certs/отозванные/' + new_name + '.crl')
  File "C:\Users\a.karpihin\AppData\Local\Programs\Python\Python39\lib\urllib\request.py", line 239, in urlretrieve
    with contextlib.closing(urlopen(url, data)) as fp:
  File "C:\Users\a.karpihin\AppData\Local\Programs\Python\Python39\lib\urllib\request.py", line 214, in urlopen
    return opener.open(url, data, timeout)
  File "C:\Users\a.karpihin\AppData\Local\Programs\Python\Python39\lib\urllib\request.py", line 517, in open
    response = self._open(req, data)
  File "C:\Users\a.karpihin\AppData\Local\Programs\Python\Python39\lib\urllib\request.py", line 534, in _open
    result = self._call_chain(self.handle_open, protocol, protocol +
  File "C:\Users\a.karpihin\AppData\Local\Programs\Python\Python39\lib\urllib\request.py", line 494, in _call_chain
    result = func(*args)
  File "C:\Users\a.karpihin\AppData\Local\Programs\Python\Python39\lib\urllib\request.py", line 1375, in http_open
    return self.do_open(http.client.HTTPConnection, req)
  File "C:\Users\a.karpihin\AppData\Local\Programs\Python\Python39\lib\urllib\request.py", line 1349, in do_open
    raise URLError(err)
urllib.error.URLError: <urlopen error [Errno 11001] getaddrinfo failed>
ERROR:root:Error for link http://parc.ru/download/cdp5/cert5_1.crl
Traceback (most recent call last):
  File "C:\Users\a.karpihin\PycharmProjects\xml_perser\main.py", line 45, in <module>
    urlreq.urlretrieve(url_link.text, 'C:/Users/a.karpihin/Desktop/certs/отозванные/' + new_name + '.crl')
  File "C:\Users\a.karpihin\AppData\Local\Programs\Python\Python39\lib\urllib\request.py", line 239, in urlretrieve
    with contextlib.closing(urlopen(url, data)) as fp:
  File "C:\Users\a.karpihin\AppData\Local\Programs\Python\Python39\lib\urllib\request.py", line 214, in urlopen
    return opener.open(url, data, timeout)
  File "C:\Users\a.karpihin\AppData\Local\Programs\Python\Python39\lib\urllib\request.py", line 523, in open
    response = meth(req, response)
  File "C:\Users\a.karpihin\AppData\Local\Programs\Python\Python39\lib\urllib\request.py", line 632, in http_response
    response = self.parent.error(
  File "C:\Users\a.karpihin\AppData\Local\Programs\Python\Python39\lib\urllib\request.py", line 561, in error
    return self._call_chain(*args)
  File "C:\Users\a.karpihin\AppData\Local\Programs\Python\Python39\lib\urllib\request.py", line 494, in _call_chain
    result = func(*args)
  File "C:\Users\a.karpihin\AppData\Local\Programs\Python\Python39\lib\urllib\request.py", line 641, in http_error_default
    raise HTTPError(req.full_url, code, msg, hdrs, fp)
urllib.error.HTTPError: HTTP Error 404: Not Found
ERROR:root:Error for link http://ra.nnov.su/cdp/ntci20.crl
Traceback (most recent call last):
  File "C:\Users\a.karpihin\AppData\Local\Programs\Python\Python39\lib\urllib\request.py", line 1346, in do_open
    h.request(req.get_method(), req.selector, req.data, headers,
  File "C:\Users\a.karpihin\AppData\Local\Programs\Python\Python39\lib\http\client.py", line 1253, in request
    self._send_request(method, url, body, headers, encode_chunked)
  File "C:\Users\a.karpihin\AppData\Local\Programs\Python\Python39\lib\http\client.py", line 1299, in _send_request
    self.endheaders(body, encode_chunked=encode_chunked)
  File "C:\Users\a.karpihin\AppData\Local\Programs\Python\Python39\lib\http\client.py", line 1248, in endheaders
    self._send_output(message_body, encode_chunked=encode_chunked)
  File "C:\Users\a.karpihin\AppData\Local\Programs\Python\Python39\lib\http\client.py", line 1008, in _send_output
    self.send(msg)
  File "C:\Users\a.karpihin\AppData\Local\Programs\Python\Python39\lib\http\client.py", line 948, in send
    self.connect()
  File "C:\Users\a.karpihin\AppData\Local\Programs\Python\Python39\lib\http\client.py", line 919, in connect
    self.sock = self._create_connection(
  File "C:\Users\a.karpihin\AppData\Local\Programs\Python\Python39\lib\socket.py", line 843, in create_connection
    raise err
  File "C:\Users\a.karpihin\AppData\Local\Programs\Python\Python39\lib\socket.py", line 831, in create_connection
    sock.connect(sa)
TimeoutError: [WinError 10060] Попытка установить соединение была безуспешной, т.к. от другого компьютера за требуемое время не получен нужный отклик, или было разорвано уже установленное соединение из-за неверного отклика уже подключенного компьютера

During handling of the above exception, another exception occurred:

Traceback (most recent call last):
  File "C:\Users\a.karpihin\PycharmProjects\xml_perser\main.py", line 45, in <module>
    urlreq.urlretrieve(url_link.text, 'C:/Users/a.karpihin/Desktop/certs/отозванные/' + new_name + '.crl')
  File "C:\Users\a.karpihin\AppData\Local\Programs\Python\Python39\lib\urllib\request.py", line 239, in urlretrieve
    with contextlib.closing(urlopen(url, data)) as fp:
  File "C:\Users\a.karpihin\AppData\Local\Programs\Python\Python39\lib\urllib\request.py", line 214, in urlopen
    return opener.open(url, data, timeout)
  File "C:\Users\a.karpihin\AppData\Local\Programs\Python\Python39\lib\urllib\request.py", line 517, in open
    response = self._open(req, data)
  File "C:\Users\a.karpihin\AppData\Local\Programs\Python\Python39\lib\urllib\request.py", line 534, in _open
    result = self._call_chain(self.handle_open, protocol, protocol +
  File "C:\Users\a.karpihin\AppData\Local\Programs\Python\Python39\lib\urllib\request.py", line 494, in _call_chain
    result = func(*args)
  File "C:\Users\a.karpihin\AppData\Local\Programs\Python\Python39\lib\urllib\request.py", line 1375, in http_open
    return self.do_open(http.client.HTTPConnection, req)
  File "C:\Users\a.karpihin\AppData\Local\Programs\Python\Python39\lib\urllib\request.py", line 1349, in do_open
    raise URLError(err)
urllib.error.URLError: <urlopen error [WinError 10060] Попытка установить соединение была безуспешной, т.к. от другого компьютера за требуемое время не получен нужный отклик, или было разорвано уже установленное соединение из-за неверного отклика уже подключенного компьютера>
ERROR:root:Error for link http://cilink.ru/cl.crl
Traceback (most recent call last):
  File "C:\Users\a.karpihin\AppData\Local\Programs\Python\Python39\lib\urllib\request.py", line 1346, in do_open
    h.request(req.get_method(), req.selector, req.data, headers,
  File "C:\Users\a.karpihin\AppData\Local\Programs\Python\Python39\lib\http\client.py", line 1253, in request
    self._send_request(method, url, body, headers, encode_chunked)
  File "C:\Users\a.karpihin\AppData\Local\Programs\Python\Python39\lib\http\client.py", line 1299, in _send_request
    self.endheaders(body, encode_chunked=encode_chunked)
  File "C:\Users\a.karpihin\AppData\Local\Programs\Python\Python39\lib\http\client.py", line 1248, in endheaders
    self._send_output(message_body, encode_chunked=encode_chunked)
  File "C:\Users\a.karpihin\AppData\Local\Programs\Python\Python39\lib\http\client.py", line 1008, in _send_output
    self.send(msg)
  File "C:\Users\a.karpihin\AppData\Local\Programs\Python\Python39\lib\http\client.py", line 948, in send
    self.connect()
  File "C:\Users\a.karpihin\AppData\Local\Programs\Python\Python39\lib\http\client.py", line 919, in connect
    self.sock = self._create_connection(
  File "C:\Users\a.karpihin\AppData\Local\Programs\Python\Python39\lib\socket.py", line 822, in create_connection
    for res in getaddrinfo(host, port, 0, SOCK_STREAM):
  File "C:\Users\a.karpihin\AppData\Local\Programs\Python\Python39\lib\socket.py", line 953, in getaddrinfo
    for res in _socket.getaddrinfo(host, port, family, type, proto, flags):
socket.gaierror: [Errno 11001] getaddrinfo failed

During handling of the above exception, another exception occurred:

Traceback (most recent call last):
  File "C:\Users\a.karpihin\PycharmProjects\xml_perser\main.py", line 45, in <module>
    urlreq.urlretrieve(url_link.text, 'C:/Users/a.karpihin/Desktop/certs/отозванные/' + new_name + '.crl')
  File "C:\Users\a.karpihin\AppData\Local\Programs\Python\Python39\lib\urllib\request.py", line 239, in urlretrieve
    with contextlib.closing(urlopen(url, data)) as fp:
  File "C:\Users\a.karpihin\AppData\Local\Programs\Python\Python39\lib\urllib\request.py", line 214, in urlopen
    return opener.open(url, data, timeout)
  File "C:\Users\a.karpihin\AppData\Local\Programs\Python\Python39\lib\urllib\request.py", line 517, in open
    response = self._open(req, data)
  File "C:\Users\a.karpihin\AppData\Local\Programs\Python\Python39\lib\urllib\request.py", line 534, in _open
    result = self._call_chain(self.handle_open, protocol, protocol +
  File "C:\Users\a.karpihin\AppData\Local\Programs\Python\Python39\lib\urllib\request.py", line 494, in _call_chain
    result = func(*args)
  File "C:\Users\a.karpihin\AppData\Local\Programs\Python\Python39\lib\urllib\request.py", line 1375, in http_open
    return self.do_open(http.client.HTTPConnection, req)
  File "C:\Users\a.karpihin\AppData\Local\Programs\Python\Python39\lib\urllib\request.py", line 1349, in do_open
    raise URLError(err)
urllib.error.URLError: <urlopen error [Errno 11001] getaddrinfo failed>
ERROR:root:Error for link http://ts1.spcom.pro/ca/7a82683ab43352d29e505a192d37e86f4650e330.crl
Traceback (most recent call last):
  File "C:\Users\a.karpihin\AppData\Local\Programs\Python\Python39\lib\urllib\request.py", line 1346, in do_open
    h.request(req.get_method(), req.selector, req.data, headers,
  File "C:\Users\a.karpihin\AppData\Local\Programs\Python\Python39\lib\http\client.py", line 1253, in request
    self._send_request(method, url, body, headers, encode_chunked)
  File "C:\Users\a.karpihin\AppData\Local\Programs\Python\Python39\lib\http\client.py", line 1299, in _send_request
    self.endheaders(body, encode_chunked=encode_chunked)
  File "C:\Users\a.karpihin\AppData\Local\Programs\Python\Python39\lib\http\client.py", line 1248, in endheaders
    self._send_output(message_body, encode_chunked=encode_chunked)
  File "C:\Users\a.karpihin\AppData\Local\Programs\Python\Python39\lib\http\client.py", line 1008, in _send_output
    self.send(msg)
  File "C:\Users\a.karpihin\AppData\Local\Programs\Python\Python39\lib\http\client.py", line 948, in send
    self.connect()
  File "C:\Users\a.karpihin\AppData\Local\Programs\Python\Python39\lib\http\client.py", line 919, in connect
    self.sock = self._create_connection(
  File "C:\Users\a.karpihin\AppData\Local\Programs\Python\Python39\lib\socket.py", line 843, in create_connection
    raise err
  File "C:\Users\a.karpihin\AppData\Local\Programs\Python\Python39\lib\socket.py", line 831, in create_connection
    sock.connect(sa)
TimeoutError: [WinError 10060] Попытка установить соединение была безуспешной, т.к. от другого компьютера за требуемое время не получен нужный отклик, или было разорвано уже установленное соединение из-за неверного отклика уже подключенного компьютера

During handling of the above exception, another exception occurred:

Traceback (most recent call last):
  File "C:\Users\a.karpihin\PycharmProjects\xml_perser\main.py", line 45, in <module>
    urlreq.urlretrieve(url_link.text, 'C:/Users/a.karpihin/Desktop/certs/отозванные/' + new_name + '.crl')
  File "C:\Users\a.karpihin\AppData\Local\Programs\Python\Python39\lib\urllib\request.py", line 239, in urlretrieve
    with contextlib.closing(urlopen(url, data)) as fp:
  File "C:\Users\a.karpihin\AppData\Local\Programs\Python\Python39\lib\urllib\request.py", line 214, in urlopen
    return opener.open(url, data, timeout)
  File "C:\Users\a.karpihin\AppData\Local\Programs\Python\Python39\lib\urllib\request.py", line 523, in open
    response = meth(req, response)
  File "C:\Users\a.karpihin\AppData\Local\Programs\Python\Python39\lib\urllib\request.py", line 632, in http_response
    response = self.parent.error(
  File "C:\Users\a.karpihin\AppData\Local\Programs\Python\Python39\lib\urllib\request.py", line 555, in error
    result = self._call_chain(*args)
  File "C:\Users\a.karpihin\AppData\Local\Programs\Python\Python39\lib\urllib\request.py", line 494, in _call_chain
    result = func(*args)
  File "C:\Users\a.karpihin\AppData\Local\Programs\Python\Python39\lib\urllib\request.py", line 747, in http_error_302
    return self.parent.open(new, timeout=req.timeout)
  File "C:\Users\a.karpihin\AppData\Local\Programs\Python\Python39\lib\urllib\request.py", line 517, in open
    response = self._open(req, data)
  File "C:\Users\a.karpihin\AppData\Local\Programs\Python\Python39\lib\urllib\request.py", line 534, in _open
    result = self._call_chain(self.handle_open, protocol, protocol +
  File "C:\Users\a.karpihin\AppData\Local\Programs\Python\Python39\lib\urllib\request.py", line 494, in _call_chain
    result = func(*args)
  File "C:\Users\a.karpihin\AppData\Local\Programs\Python\Python39\lib\urllib\request.py", line 1375, in http_open
    return self.do_open(http.client.HTTPConnection, req)
  File "C:\Users\a.karpihin\AppData\Local\Programs\Python\Python39\lib\urllib\request.py", line 1349, in do_open
    raise URLError(err)
urllib.error.URLError: <urlopen error [WinError 10060] Попытка установить соединение была безуспешной, т.к. от другого компьютера за требуемое время не получен нужный отклик, или было разорвано уже установленное соединение из-за неверного отклика уже подключенного компьютера>
ERROR:root:Error for link http://ra.elkursk.ru/ra/cdp/6613494272D0E900737E6254F036F890A43D8BC5.crl
Traceback (most recent call last):
  File "C:\Users\a.karpihin\PycharmProjects\xml_perser\main.py", line 45, in <module>
    urlreq.urlretrieve(url_link.text, 'C:/Users/a.karpihin/Desktop/certs/отозванные/' + new_name + '.crl')
  File "C:\Users\a.karpihin\AppData\Local\Programs\Python\Python39\lib\urllib\request.py", line 239, in urlretrieve
    with contextlib.closing(urlopen(url, data)) as fp:
  File "C:\Users\a.karpihin\AppData\Local\Programs\Python\Python39\lib\urllib\request.py", line 214, in urlopen
    return opener.open(url, data, timeout)
  File "C:\Users\a.karpihin\AppData\Local\Programs\Python\Python39\lib\urllib\request.py", line 523, in open
    response = meth(req, response)
  File "C:\Users\a.karpihin\AppData\Local\Programs\Python\Python39\lib\urllib\request.py", line 632, in http_response
    response = self.parent.error(
  File "C:\Users\a.karpihin\AppData\Local\Programs\Python\Python39\lib\urllib\request.py", line 561, in error
    return self._call_chain(*args)
  File "C:\Users\a.karpihin\AppData\Local\Programs\Python\Python39\lib\urllib\request.py", line 494, in _call_chain
    result = func(*args)
  File "C:\Users\a.karpihin\AppData\Local\Programs\Python\Python39\lib\urllib\request.py", line 641, in http_error_default
    raise HTTPError(req.full_url, code, msg, hdrs, fp)
urllib.error.HTTPError: HTTP Error 403: Forbidden
ERROR:root:Error for link http://ca.orbitacom.ru/cdp/245c77ee327803ef34fdcdc7d01f803cc1ca61b4.crl
Traceback (most recent call last):
  File "C:\Users\a.karpihin\AppData\Local\Programs\Python\Python39\lib\urllib\request.py", line 1346, in do_open
    h.request(req.get_method(), req.selector, req.data, headers,
  File "C:\Users\a.karpihin\AppData\Local\Programs\Python\Python39\lib\http\client.py", line 1253, in request
    self._send_request(method, url, body, headers, encode_chunked)
  File "C:\Users\a.karpihin\AppData\Local\Programs\Python\Python39\lib\http\client.py", line 1299, in _send_request
    self.endheaders(body, encode_chunked=encode_chunked)
  File "C:\Users\a.karpihin\AppData\Local\Programs\Python\Python39\lib\http\client.py", line 1248, in endheaders
    self._send_output(message_body, encode_chunked=encode_chunked)
  File "C:\Users\a.karpihin\AppData\Local\Programs\Python\Python39\lib\http\client.py", line 1008, in _send_output
    self.send(msg)
  File "C:\Users\a.karpihin\AppData\Local\Programs\Python\Python39\lib\http\client.py", line 948, in send
    self.connect()
  File "C:\Users\a.karpihin\AppData\Local\Programs\Python\Python39\lib\http\client.py", line 919, in connect
    self.sock = self._create_connection(
  File "C:\Users\a.karpihin\AppData\Local\Programs\Python\Python39\lib\socket.py", line 843, in create_connection
    raise err
  File "C:\Users\a.karpihin\AppData\Local\Programs\Python\Python39\lib\socket.py", line 831, in create_connection
    sock.connect(sa)
TimeoutError: [WinError 10060] Попытка установить соединение была безуспешной, т.к. от другого компьютера за требуемое время не получен нужный отклик, или было разорвано уже установленное соединение из-за неверного отклика уже подключенного компьютера

During handling of the above exception, another exception occurred:

Traceback (most recent call last):
  File "C:\Users\a.karpihin\PycharmProjects\xml_perser\main.py", line 45, in <module>
    urlreq.urlretrieve(url_link.text, 'C:/Users/a.karpihin/Desktop/certs/отозванные/' + new_name + '.crl')
  File "C:\Users\a.karpihin\AppData\Local\Programs\Python\Python39\lib\urllib\request.py", line 239, in urlretrieve
    with contextlib.closing(urlopen(url, data)) as fp:
  File "C:\Users\a.karpihin\AppData\Local\Programs\Python\Python39\lib\urllib\request.py", line 214, in urlopen
    return opener.open(url, data, timeout)
  File "C:\Users\a.karpihin\AppData\Local\Programs\Python\Python39\lib\urllib\request.py", line 517, in open
    response = self._open(req, data)
  File "C:\Users\a.karpihin\AppData\Local\Programs\Python\Python39\lib\urllib\request.py", line 534, in _open
    result = self._call_chain(self.handle_open, protocol, protocol +
  File "C:\Users\a.karpihin\AppData\Local\Programs\Python\Python39\lib\urllib\request.py", line 494, in _call_chain
    result = func(*args)
  File "C:\Users\a.karpihin\AppData\Local\Programs\Python\Python39\lib\urllib\request.py", line 1375, in http_open
    return self.do_open(http.client.HTTPConnection, req)
  File "C:\Users\a.karpihin\AppData\Local\Programs\Python\Python39\lib\urllib\request.py", line 1349, in do_open
    raise URLError(err)
urllib.error.URLError: <urlopen error [WinError 10060] Попытка установить соединение была безуспешной, т.к. от другого компьютера за требуемое время не получен нужный отклик, или было разорвано уже установленное соединение из-за неверного отклика уже подключенного компьютера>
ERROR:root:Error for link http://cr.profi-uc.ru/download/CA_PROFI.crl
Traceback (most recent call last):
  File "C:\Users\a.karpihin\AppData\Local\Programs\Python\Python39\lib\urllib\request.py", line 1346, in do_open
    h.request(req.get_method(), req.selector, req.data, headers,
  File "C:\Users\a.karpihin\AppData\Local\Programs\Python\Python39\lib\http\client.py", line 1253, in request
    self._send_request(method, url, body, headers, encode_chunked)
  File "C:\Users\a.karpihin\AppData\Local\Programs\Python\Python39\lib\http\client.py", line 1299, in _send_request
    self.endheaders(body, encode_chunked=encode_chunked)
  File "C:\Users\a.karpihin\AppData\Local\Programs\Python\Python39\lib\http\client.py", line 1248, in endheaders
    self._send_output(message_body, encode_chunked=encode_chunked)
  File "C:\Users\a.karpihin\AppData\Local\Programs\Python\Python39\lib\http\client.py", line 1008, in _send_output
    self.send(msg)
  File "C:\Users\a.karpihin\AppData\Local\Programs\Python\Python39\lib\http\client.py", line 948, in send
    self.connect()
  File "C:\Users\a.karpihin\AppData\Local\Programs\Python\Python39\lib\http\client.py", line 919, in connect
    self.sock = self._create_connection(
  File "C:\Users\a.karpihin\AppData\Local\Programs\Python\Python39\lib\socket.py", line 843, in create_connection
    raise err
  File "C:\Users\a.karpihin\AppData\Local\Programs\Python\Python39\lib\socket.py", line 831, in create_connection
    sock.connect(sa)
TimeoutError: [WinError 10060] Попытка установить соединение была безуспешной, т.к. от другого компьютера за требуемое время не получен нужный отклик, или было разорвано уже установленное соединение из-за неверного отклика уже подключенного компьютера

During handling of the above exception, another exception occurred:

Traceback (most recent call last):
  File "C:\Users\a.karpihin\PycharmProjects\xml_perser\main.py", line 45, in <module>
    urlreq.urlretrieve(url_link.text, 'C:/Users/a.karpihin/Desktop/certs/отозванные/' + new_name + '.crl')
  File "C:\Users\a.karpihin\AppData\Local\Programs\Python\Python39\lib\urllib\request.py", line 239, in urlretrieve
    with contextlib.closing(urlopen(url, data)) as fp:
  File "C:\Users\a.karpihin\AppData\Local\Programs\Python\Python39\lib\urllib\request.py", line 214, in urlopen
    return opener.open(url, data, timeout)
  File "C:\Users\a.karpihin\AppData\Local\Programs\Python\Python39\lib\urllib\request.py", line 517, in open
    response = self._open(req, data)
  File "C:\Users\a.karpihin\AppData\Local\Programs\Python\Python39\lib\urllib\request.py", line 534, in _open
    result = self._call_chain(self.handle_open, protocol, protocol +
  File "C:\Users\a.karpihin\AppData\Local\Programs\Python\Python39\lib\urllib\request.py", line 494, in _call_chain
    result = func(*args)
  File "C:\Users\a.karpihin\AppData\Local\Programs\Python\Python39\lib\urllib\request.py", line 1375, in http_open
    return self.do_open(http.client.HTTPConnection, req)
  File "C:\Users\a.karpihin\AppData\Local\Programs\Python\Python39\lib\urllib\request.py", line 1349, in do_open
    raise URLError(err)
urllib.error.URLError: <urlopen error [WinError 10060] Попытка установить соединение была безуспешной, т.к. от другого компьютера за требуемое время не получен нужный отклик, или было разорвано уже установленное соединение из-за неверного отклика уже подключенного компьютера>
ERROR:root:Error for link http://vipnet.skc.ru/oldcrl
Traceback (most recent call last):
  File "C:\Users\a.karpihin\AppData\Local\Programs\Python\Python39\lib\urllib\request.py", line 1346, in do_open
    h.request(req.get_method(), req.selector, req.data, headers,
  File "C:\Users\a.karpihin\AppData\Local\Programs\Python\Python39\lib\http\client.py", line 1253, in request
    self._send_request(method, url, body, headers, encode_chunked)
  File "C:\Users\a.karpihin\AppData\Local\Programs\Python\Python39\lib\http\client.py", line 1299, in _send_request
    self.endheaders(body, encode_chunked=encode_chunked)
  File "C:\Users\a.karpihin\AppData\Local\Programs\Python\Python39\lib\http\client.py", line 1248, in endheaders
    self._send_output(message_body, encode_chunked=encode_chunked)
  File "C:\Users\a.karpihin\AppData\Local\Programs\Python\Python39\lib\http\client.py", line 1008, in _send_output
    self.send(msg)
  File "C:\Users\a.karpihin\AppData\Local\Programs\Python\Python39\lib\http\client.py", line 948, in send
    self.connect()
  File "C:\Users\a.karpihin\AppData\Local\Programs\Python\Python39\lib\http\client.py", line 1422, in connect
    self.sock = self._context.wrap_socket(self.sock,
  File "C:\Users\a.karpihin\AppData\Local\Programs\Python\Python39\lib\ssl.py", line 500, in wrap_socket
    return self.sslsocket_class._create(
  File "C:\Users\a.karpihin\AppData\Local\Programs\Python\Python39\lib\ssl.py", line 1040, in _create
    self.do_handshake()
  File "C:\Users\a.karpihin\AppData\Local\Programs\Python\Python39\lib\ssl.py", line 1309, in do_handshake
    self._sslobj.do_handshake()
ssl.SSLCertVerificationError: [SSL: CERTIFICATE_VERIFY_FAILED] certificate verify failed: unable to get local issuer certificate (_ssl.c:1129)

During handling of the above exception, another exception occurred:

Traceback (most recent call last):
  File "C:\Users\a.karpihin\PycharmProjects\xml_perser\main.py", line 45, in <module>
    urlreq.urlretrieve(url_link.text, 'C:/Users/a.karpihin/Desktop/certs/отозванные/' + new_name + '.crl')
  File "C:\Users\a.karpihin\AppData\Local\Programs\Python\Python39\lib\urllib\request.py", line 239, in urlretrieve
    with contextlib.closing(urlopen(url, data)) as fp:
  File "C:\Users\a.karpihin\AppData\Local\Programs\Python\Python39\lib\urllib\request.py", line 214, in urlopen
    return opener.open(url, data, timeout)
  File "C:\Users\a.karpihin\AppData\Local\Programs\Python\Python39\lib\urllib\request.py", line 523, in open
    response = meth(req, response)
  File "C:\Users\a.karpihin\AppData\Local\Programs\Python\Python39\lib\urllib\request.py", line 632, in http_response
    response = self.parent.error(
  File "C:\Users\a.karpihin\AppData\Local\Programs\Python\Python39\lib\urllib\request.py", line 555, in error
    result = self._call_chain(*args)
  File "C:\Users\a.karpihin\AppData\Local\Programs\Python\Python39\lib\urllib\request.py", line 494, in _call_chain
    result = func(*args)
  File "C:\Users\a.karpihin\AppData\Local\Programs\Python\Python39\lib\urllib\request.py", line 747, in http_error_302
    return self.parent.open(new, timeout=req.timeout)
  File "C:\Users\a.karpihin\AppData\Local\Programs\Python\Python39\lib\urllib\request.py", line 517, in open
    response = self._open(req, data)
  File "C:\Users\a.karpihin\AppData\Local\Programs\Python\Python39\lib\urllib\request.py", line 534, in _open
    result = self._call_chain(self.handle_open, protocol, protocol +
  File "C:\Users\a.karpihin\AppData\Local\Programs\Python\Python39\lib\urllib\request.py", line 494, in _call_chain
    result = func(*args)
  File "C:\Users\a.karpihin\AppData\Local\Programs\Python\Python39\lib\urllib\request.py", line 1389, in https_open
    return self.do_open(http.client.HTTPSConnection, req,
  File "C:\Users\a.karpihin\AppData\Local\Programs\Python\Python39\lib\urllib\request.py", line 1349, in do_open
    raise URLError(err)
urllib.error.URLError: <urlopen error [SSL: CERTIFICATE_VERIFY_FAILED] certificate verify failed: unable to get local issuer certificate (_ssl.c:1129)>
ERROR:root:Error for link http://ca.nrcrf.ru/cdp/canrc14.crl
Traceback (most recent call last):
  File "C:\Users\a.karpihin\AppData\Local\Programs\Python\Python39\lib\urllib\request.py", line 1346, in do_open
    h.request(req.get_method(), req.selector, req.data, headers,
  File "C:\Users\a.karpihin\AppData\Local\Programs\Python\Python39\lib\http\client.py", line 1253, in request
    self._send_request(method, url, body, headers, encode_chunked)
  File "C:\Users\a.karpihin\AppData\Local\Programs\Python\Python39\lib\http\client.py", line 1299, in _send_request
    self.endheaders(body, encode_chunked=encode_chunked)
  File "C:\Users\a.karpihin\AppData\Local\Programs\Python\Python39\lib\http\client.py", line 1248, in endheaders
    self._send_output(message_body, encode_chunked=encode_chunked)
  File "C:\Users\a.karpihin\AppData\Local\Programs\Python\Python39\lib\http\client.py", line 1008, in _send_output
    self.send(msg)
  File "C:\Users\a.karpihin\AppData\Local\Programs\Python\Python39\lib\http\client.py", line 948, in send
    self.connect()
  File "C:\Users\a.karpihin\AppData\Local\Programs\Python\Python39\lib\http\client.py", line 919, in connect
    self.sock = self._create_connection(
  File "C:\Users\a.karpihin\AppData\Local\Programs\Python\Python39\lib\socket.py", line 822, in create_connection
    for res in getaddrinfo(host, port, 0, SOCK_STREAM):
  File "C:\Users\a.karpihin\AppData\Local\Programs\Python\Python39\lib\socket.py", line 953, in getaddrinfo
    for res in _socket.getaddrinfo(host, port, family, type, proto, flags):
socket.gaierror: [Errno 11001] getaddrinfo failed

During handling of the above exception, another exception occurred:

Traceback (most recent call last):
  File "C:\Users\a.karpihin\PycharmProjects\xml_perser\main.py", line 45, in <module>
    urlreq.urlretrieve(url_link.text, 'C:/Users/a.karpihin/Desktop/certs/отозванные/' + new_name + '.crl')
  File "C:\Users\a.karpihin\AppData\Local\Programs\Python\Python39\lib\urllib\request.py", line 239, in urlretrieve
    with contextlib.closing(urlopen(url, data)) as fp:
  File "C:\Users\a.karpihin\AppData\Local\Programs\Python\Python39\lib\urllib\request.py", line 214, in urlopen
    return opener.open(url, data, timeout)
  File "C:\Users\a.karpihin\AppData\Local\Programs\Python\Python39\lib\urllib\request.py", line 517, in open
    response = self._open(req, data)
  File "C:\Users\a.karpihin\AppData\Local\Programs\Python\Python39\lib\urllib\request.py", line 534, in _open
    result = self._call_chain(self.handle_open, protocol, protocol +
  File "C:\Users\a.karpihin\AppData\Local\Programs\Python\Python39\lib\urllib\request.py", line 494, in _call_chain
    result = func(*args)
  File "C:\Users\a.karpihin\AppData\Local\Programs\Python\Python39\lib\urllib\request.py", line 1375, in http_open
    return self.do_open(http.client.HTTPConnection, req)
  File "C:\Users\a.karpihin\AppData\Local\Programs\Python\Python39\lib\urllib\request.py", line 1349, in do_open
    raise URLError(err)
urllib.error.URLError: <urlopen error [Errno 11001] getaddrinfo failed>
ERROR:root:Error for link http://ca01.arbitr.ru/pub/crl/cacrl.crl
Traceback (most recent call last):
  File "C:\Users\a.karpihin\AppData\Local\Programs\Python\Python39\lib\urllib\request.py", line 1346, in do_open
    h.request(req.get_method(), req.selector, req.data, headers,
  File "C:\Users\a.karpihin\AppData\Local\Programs\Python\Python39\lib\http\client.py", line 1253, in request
    self._send_request(method, url, body, headers, encode_chunked)
  File "C:\Users\a.karpihin\AppData\Local\Programs\Python\Python39\lib\http\client.py", line 1299, in _send_request
    self.endheaders(body, encode_chunked=encode_chunked)
  File "C:\Users\a.karpihin\AppData\Local\Programs\Python\Python39\lib\http\client.py", line 1248, in endheaders
    self._send_output(message_body, encode_chunked=encode_chunked)
  File "C:\Users\a.karpihin\AppData\Local\Programs\Python\Python39\lib\http\client.py", line 1008, in _send_output
    self.send(msg)
  File "C:\Users\a.karpihin\AppData\Local\Programs\Python\Python39\lib\http\client.py", line 948, in send
    self.connect()
  File "C:\Users\a.karpihin\AppData\Local\Programs\Python\Python39\lib\http\client.py", line 919, in connect
    self.sock = self._create_connection(
  File "C:\Users\a.karpihin\AppData\Local\Programs\Python\Python39\lib\socket.py", line 843, in create_connection
    raise err
  File "C:\Users\a.karpihin\AppData\Local\Programs\Python\Python39\lib\socket.py", line 831, in create_connection
    sock.connect(sa)
TimeoutError: [WinError 10060] Попытка установить соединение была безуспешной, т.к. от другого компьютера за требуемое время не получен нужный отклик, или было разорвано уже установленное соединение из-за неверного отклика уже подключенного компьютера

During handling of the above exception, another exception occurred:

Traceback (most recent call last):
  File "C:\Users\a.karpihin\PycharmProjects\xml_perser\main.py", line 45, in <module>
    urlreq.urlretrieve(url_link.text, 'C:/Users/a.karpihin/Desktop/certs/отозванные/' + new_name + '.crl')
  File "C:\Users\a.karpihin\AppData\Local\Programs\Python\Python39\lib\urllib\request.py", line 239, in urlretrieve
    with contextlib.closing(urlopen(url, data)) as fp:
  File "C:\Users\a.karpihin\AppData\Local\Programs\Python\Python39\lib\urllib\request.py", line 214, in urlopen
    return opener.open(url, data, timeout)
  File "C:\Users\a.karpihin\AppData\Local\Programs\Python\Python39\lib\urllib\request.py", line 517, in open
    response = self._open(req, data)
  File "C:\Users\a.karpihin\AppData\Local\Programs\Python\Python39\lib\urllib\request.py", line 534, in _open
    result = self._call_chain(self.handle_open, protocol, protocol +
  File "C:\Users\a.karpihin\AppData\Local\Programs\Python\Python39\lib\urllib\request.py", line 494, in _call_chain
    result = func(*args)
  File "C:\Users\a.karpihin\AppData\Local\Programs\Python\Python39\lib\urllib\request.py", line 1375, in http_open
    return self.do_open(http.client.HTTPConnection, req)
  File "C:\Users\a.karpihin\AppData\Local\Programs\Python\Python39\lib\urllib\request.py", line 1349, in do_open
    raise URLError(err)
urllib.error.URLError: <urlopen error [WinError 10060] Попытка установить соединение была безуспешной, т.к. от другого компьютера за требуемое время не получен нужный отклик, или было разорвано уже установленное соединение из-за неверного отклика уже подключенного компьютера>
ERROR:root:Error for link http://pki.obrnadzor.gov.ru/ca/cdp/ogca-2015.crl
Traceback (most recent call last):
  File "C:\Users\a.karpihin\AppData\Local\Programs\Python\Python39\lib\urllib\request.py", line 1346, in do_open
    h.request(req.get_method(), req.selector, req.data, headers,
  File "C:\Users\a.karpihin\AppData\Local\Programs\Python\Python39\lib\http\client.py", line 1253, in request
    self._send_request(method, url, body, headers, encode_chunked)
  File "C:\Users\a.karpihin\AppData\Local\Programs\Python\Python39\lib\http\client.py", line 1299, in _send_request
    self.endheaders(body, encode_chunked=encode_chunked)
  File "C:\Users\a.karpihin\AppData\Local\Programs\Python\Python39\lib\http\client.py", line 1248, in endheaders
    self._send_output(message_body, encode_chunked=encode_chunked)
  File "C:\Users\a.karpihin\AppData\Local\Programs\Python\Python39\lib\http\client.py", line 1008, in _send_output
    self.send(msg)
  File "C:\Users\a.karpihin\AppData\Local\Programs\Python\Python39\lib\http\client.py", line 948, in send
    self.connect()
  File "C:\Users\a.karpihin\AppData\Local\Programs\Python\Python39\lib\http\client.py", line 919, in connect
    self.sock = self._create_connection(
  File "C:\Users\a.karpihin\AppData\Local\Programs\Python\Python39\lib\socket.py", line 822, in create_connection
    for res in getaddrinfo(host, port, 0, SOCK_STREAM):
  File "C:\Users\a.karpihin\AppData\Local\Programs\Python\Python39\lib\socket.py", line 953, in getaddrinfo
    for res in _socket.getaddrinfo(host, port, family, type, proto, flags):
socket.gaierror: [Errno 11001] getaddrinfo failed

During handling of the above exception, another exception occurred:

Traceback (most recent call last):
  File "C:\Users\a.karpihin\PycharmProjects\xml_perser\main.py", line 45, in <module>
    urlreq.urlretrieve(url_link.text, 'C:/Users/a.karpihin/Desktop/certs/отозванные/' + new_name + '.crl')
  File "C:\Users\a.karpihin\AppData\Local\Programs\Python\Python39\lib\urllib\request.py", line 239, in urlretrieve
    with contextlib.closing(urlopen(url, data)) as fp:
  File "C:\Users\a.karpihin\AppData\Local\Programs\Python\Python39\lib\urllib\request.py", line 214, in urlopen
    return opener.open(url, data, timeout)
  File "C:\Users\a.karpihin\AppData\Local\Programs\Python\Python39\lib\urllib\request.py", line 517, in open
    response = self._open(req, data)
  File "C:\Users\a.karpihin\AppData\Local\Programs\Python\Python39\lib\urllib\request.py", line 534, in _open
    result = self._call_chain(self.handle_open, protocol, protocol +
  File "C:\Users\a.karpihin\AppData\Local\Programs\Python\Python39\lib\urllib\request.py", line 494, in _call_chain
    result = func(*args)
  File "C:\Users\a.karpihin\AppData\Local\Programs\Python\Python39\lib\urllib\request.py", line 1375, in http_open
    return self.do_open(http.client.HTTPConnection, req)
  File "C:\Users\a.karpihin\AppData\Local\Programs\Python\Python39\lib\urllib\request.py", line 1349, in do_open
    raise URLError(err)
urllib.error.URLError: <urlopen error [Errno 11001] getaddrinfo failed>
ERROR:root:Error for link http://budget.mos.ru/service2/certcallback/upload/e2cee2ca428e7aeeecd74a3ac5d611620dcd1ef8.crl
Traceback (most recent call last):
  File "C:\Users\a.karpihin\PycharmProjects\xml_perser\main.py", line 45, in <module>
    urlreq.urlretrieve(url_link.text, 'C:/Users/a.karpihin/Desktop/certs/отозванные/' + new_name + '.crl')
  File "C:\Users\a.karpihin\AppData\Local\Programs\Python\Python39\lib\urllib\request.py", line 239, in urlretrieve
    with contextlib.closing(urlopen(url, data)) as fp:
  File "C:\Users\a.karpihin\AppData\Local\Programs\Python\Python39\lib\urllib\request.py", line 214, in urlopen
    return opener.open(url, data, timeout)
  File "C:\Users\a.karpihin\AppData\Local\Programs\Python\Python39\lib\urllib\request.py", line 523, in open
    response = meth(req, response)
  File "C:\Users\a.karpihin\AppData\Local\Programs\Python\Python39\lib\urllib\request.py", line 632, in http_response
    response = self.parent.error(
  File "C:\Users\a.karpihin\AppData\Local\Programs\Python\Python39\lib\urllib\request.py", line 555, in error
    result = self._call_chain(*args)
  File "C:\Users\a.karpihin\AppData\Local\Programs\Python\Python39\lib\urllib\request.py", line 494, in _call_chain
    result = func(*args)
  File "C:\Users\a.karpihin\AppData\Local\Programs\Python\Python39\lib\urllib\request.py", line 747, in http_error_302
    return self.parent.open(new, timeout=req.timeout)
  File "C:\Users\a.karpihin\AppData\Local\Programs\Python\Python39\lib\urllib\request.py", line 523, in open
    response = meth(req, response)
  File "C:\Users\a.karpihin\AppData\Local\Programs\Python\Python39\lib\urllib\request.py", line 632, in http_response
    response = self.parent.error(
  File "C:\Users\a.karpihin\AppData\Local\Programs\Python\Python39\lib\urllib\request.py", line 561, in error
    return self._call_chain(*args)
  File "C:\Users\a.karpihin\AppData\Local\Programs\Python\Python39\lib\urllib\request.py", line 494, in _call_chain
    result = func(*args)
  File "C:\Users\a.karpihin\AppData\Local\Programs\Python\Python39\lib\urllib\request.py", line 641, in http_error_default
    raise HTTPError(req.full_url, code, msg, hdrs, fp)
urllib.error.HTTPError: HTTP Error 404: Not Found
ERROR:root:Error for link http://wcsmr.ru/ca/list.crl
Traceback (most recent call last):
  File "C:\Users\a.karpihin\AppData\Local\Programs\Python\Python39\lib\urllib\request.py", line 1346, in do_open
    h.request(req.get_method(), req.selector, req.data, headers,
  File "C:\Users\a.karpihin\AppData\Local\Programs\Python\Python39\lib\http\client.py", line 1253, in request
    self._send_request(method, url, body, headers, encode_chunked)
  File "C:\Users\a.karpihin\AppData\Local\Programs\Python\Python39\lib\http\client.py", line 1299, in _send_request
    self.endheaders(body, encode_chunked=encode_chunked)
  File "C:\Users\a.karpihin\AppData\Local\Programs\Python\Python39\lib\http\client.py", line 1248, in endheaders
    self._send_output(message_body, encode_chunked=encode_chunked)
  File "C:\Users\a.karpihin\AppData\Local\Programs\Python\Python39\lib\http\client.py", line 1008, in _send_output
    self.send(msg)
  File "C:\Users\a.karpihin\AppData\Local\Programs\Python\Python39\lib\http\client.py", line 948, in send
    self.connect()
  File "C:\Users\a.karpihin\AppData\Local\Programs\Python\Python39\lib\http\client.py", line 919, in connect
    self.sock = self._create_connection(
  File "C:\Users\a.karpihin\AppData\Local\Programs\Python\Python39\lib\socket.py", line 822, in create_connection
    for res in getaddrinfo(host, port, 0, SOCK_STREAM):
  File "C:\Users\a.karpihin\AppData\Local\Programs\Python\Python39\lib\socket.py", line 953, in getaddrinfo
    for res in _socket.getaddrinfo(host, port, family, type, proto, flags):
socket.gaierror: [Errno 11001] getaddrinfo failed

During handling of the above exception, another exception occurred:

Traceback (most recent call last):
  File "C:\Users\a.karpihin\PycharmProjects\xml_perser\main.py", line 45, in <module>
    urlreq.urlretrieve(url_link.text, 'C:/Users/a.karpihin/Desktop/certs/отозванные/' + new_name + '.crl')
  File "C:\Users\a.karpihin\AppData\Local\Programs\Python\Python39\lib\urllib\request.py", line 239, in urlretrieve
    with contextlib.closing(urlopen(url, data)) as fp:
  File "C:\Users\a.karpihin\AppData\Local\Programs\Python\Python39\lib\urllib\request.py", line 214, in urlopen
    return opener.open(url, data, timeout)
  File "C:\Users\a.karpihin\AppData\Local\Programs\Python\Python39\lib\urllib\request.py", line 517, in open
    response = self._open(req, data)
  File "C:\Users\a.karpihin\AppData\Local\Programs\Python\Python39\lib\urllib\request.py", line 534, in _open
    result = self._call_chain(self.handle_open, protocol, protocol +
  File "C:\Users\a.karpihin\AppData\Local\Programs\Python\Python39\lib\urllib\request.py", line 494, in _call_chain
    result = func(*args)
  File "C:\Users\a.karpihin\AppData\Local\Programs\Python\Python39\lib\urllib\request.py", line 1375, in http_open
    return self.do_open(http.client.HTTPConnection, req)
  File "C:\Users\a.karpihin\AppData\Local\Programs\Python\Python39\lib\urllib\request.py", line 1349, in do_open
    raise URLError(err)
urllib.error.URLError: <urlopen error [Errno 11001] getaddrinfo failed>
ERROR:root:Error for link http://www.otchetnost.spb.ru/uc1cert5.crl
Traceback (most recent call last):
  File "C:\Users\a.karpihin\PycharmProjects\xml_perser\main.py", line 45, in <module>
    urlreq.urlretrieve(url_link.text, 'C:/Users/a.karpihin/Desktop/certs/отозванные/' + new_name + '.crl')
  File "C:\Users\a.karpihin\AppData\Local\Programs\Python\Python39\lib\urllib\request.py", line 239, in urlretrieve
    with contextlib.closing(urlopen(url, data)) as fp:
  File "C:\Users\a.karpihin\AppData\Local\Programs\Python\Python39\lib\urllib\request.py", line 214, in urlopen
    return opener.open(url, data, timeout)
  File "C:\Users\a.karpihin\AppData\Local\Programs\Python\Python39\lib\urllib\request.py", line 523, in open
    response = meth(req, response)
  File "C:\Users\a.karpihin\AppData\Local\Programs\Python\Python39\lib\urllib\request.py", line 632, in http_response
    response = self.parent.error(
  File "C:\Users\a.karpihin\AppData\Local\Programs\Python\Python39\lib\urllib\request.py", line 561, in error
    return self._call_chain(*args)
  File "C:\Users\a.karpihin\AppData\Local\Programs\Python\Python39\lib\urllib\request.py", line 494, in _call_chain
    result = func(*args)
  File "C:\Users\a.karpihin\AppData\Local\Programs\Python\Python39\lib\urllib\request.py", line 641, in http_error_default
    raise HTTPError(req.full_url, code, msg, hdrs, fp)
urllib.error.HTTPError: HTTP Error 503: Service Unavailable
ERROR:root:Error for link http://fc.russianpost.ru/DownLoad/For_Site/Uslugi/NormDoc/ca-I2GV2BUM76NS38TX.crl
Traceback (most recent call last):
  File "C:\Users\a.karpihin\PycharmProjects\xml_perser\main.py", line 45, in <module>
    urlreq.urlretrieve(url_link.text, 'C:/Users/a.karpihin/Desktop/certs/отозванные/' + new_name + '.crl')
  File "C:\Users\a.karpihin\AppData\Local\Programs\Python\Python39\lib\urllib\request.py", line 239, in urlretrieve
    with contextlib.closing(urlopen(url, data)) as fp:
  File "C:\Users\a.karpihin\AppData\Local\Programs\Python\Python39\lib\urllib\request.py", line 214, in urlopen
    return opener.open(url, data, timeout)
  File "C:\Users\a.karpihin\AppData\Local\Programs\Python\Python39\lib\urllib\request.py", line 523, in open
    response = meth(req, response)
  File "C:\Users\a.karpihin\AppData\Local\Programs\Python\Python39\lib\urllib\request.py", line 632, in http_response
    response = self.parent.error(
  File "C:\Users\a.karpihin\AppData\Local\Programs\Python\Python39\lib\urllib\request.py", line 555, in error
    result = self._call_chain(*args)
  File "C:\Users\a.karpihin\AppData\Local\Programs\Python\Python39\lib\urllib\request.py", line 494, in _call_chain
    result = func(*args)
  File "C:\Users\a.karpihin\AppData\Local\Programs\Python\Python39\lib\urllib\request.py", line 747, in http_error_302
    return self.parent.open(new, timeout=req.timeout)
  File "C:\Users\a.karpihin\AppData\Local\Programs\Python\Python39\lib\urllib\request.py", line 523, in open
    response = meth(req, response)
  File "C:\Users\a.karpihin\AppData\Local\Programs\Python\Python39\lib\urllib\request.py", line 632, in http_response
    response = self.parent.error(
  File "C:\Users\a.karpihin\AppData\Local\Programs\Python\Python39\lib\urllib\request.py", line 561, in error
    return self._call_chain(*args)
  File "C:\Users\a.karpihin\AppData\Local\Programs\Python\Python39\lib\urllib\request.py", line 494, in _call_chain
    result = func(*args)
  File "C:\Users\a.karpihin\AppData\Local\Programs\Python\Python39\lib\urllib\request.py", line 641, in http_error_default
    raise HTTPError(req.full_url, code, msg, hdrs, fp)
urllib.error.HTTPError: HTTP Error 404: Not Found
ERROR:root:Error for link http://ca.genuc.ru/cdp/genuc-2018.crl
Traceback (most recent call last):
  File "C:\Users\a.karpihin\AppData\Local\Programs\Python\Python39\lib\urllib\request.py", line 1346, in do_open
    h.request(req.get_method(), req.selector, req.data, headers,
  File "C:\Users\a.karpihin\AppData\Local\Programs\Python\Python39\lib\http\client.py", line 1253, in request
    self._send_request(method, url, body, headers, encode_chunked)
  File "C:\Users\a.karpihin\AppData\Local\Programs\Python\Python39\lib\http\client.py", line 1299, in _send_request
    self.endheaders(body, encode_chunked=encode_chunked)
  File "C:\Users\a.karpihin\AppData\Local\Programs\Python\Python39\lib\http\client.py", line 1248, in endheaders
    self._send_output(message_body, encode_chunked=encode_chunked)
  File "C:\Users\a.karpihin\AppData\Local\Programs\Python\Python39\lib\http\client.py", line 1008, in _send_output
    self.send(msg)
  File "C:\Users\a.karpihin\AppData\Local\Programs\Python\Python39\lib\http\client.py", line 948, in send
    self.connect()
  File "C:\Users\a.karpihin\AppData\Local\Programs\Python\Python39\lib\http\client.py", line 919, in connect
    self.sock = self._create_connection(
  File "C:\Users\a.karpihin\AppData\Local\Programs\Python\Python39\lib\socket.py", line 822, in create_connection
    for res in getaddrinfo(host, port, 0, SOCK_STREAM):
  File "C:\Users\a.karpihin\AppData\Local\Programs\Python\Python39\lib\socket.py", line 953, in getaddrinfo
    for res in _socket.getaddrinfo(host, port, family, type, proto, flags):
socket.gaierror: [Errno 11001] getaddrinfo failed

During handling of the above exception, another exception occurred:

Traceback (most recent call last):
  File "C:\Users\a.karpihin\PycharmProjects\xml_perser\main.py", line 45, in <module>
    urlreq.urlretrieve(url_link.text, 'C:/Users/a.karpihin/Desktop/certs/отозванные/' + new_name + '.crl')
  File "C:\Users\a.karpihin\AppData\Local\Programs\Python\Python39\lib\urllib\request.py", line 239, in urlretrieve
    with contextlib.closing(urlopen(url, data)) as fp:
  File "C:\Users\a.karpihin\AppData\Local\Programs\Python\Python39\lib\urllib\request.py", line 214, in urlopen
    return opener.open(url, data, timeout)
  File "C:\Users\a.karpihin\AppData\Local\Programs\Python\Python39\lib\urllib\request.py", line 517, in open
    response = self._open(req, data)
  File "C:\Users\a.karpihin\AppData\Local\Programs\Python\Python39\lib\urllib\request.py", line 534, in _open
    result = self._call_chain(self.handle_open, protocol, protocol +
  File "C:\Users\a.karpihin\AppData\Local\Programs\Python\Python39\lib\urllib\request.py", line 494, in _call_chain
    result = func(*args)
  File "C:\Users\a.karpihin\AppData\Local\Programs\Python\Python39\lib\urllib\request.py", line 1375, in http_open
    return self.do_open(http.client.HTTPConnection, req)
  File "C:\Users\a.karpihin\AppData\Local\Programs\Python\Python39\lib\urllib\request.py", line 1349, in do_open
    raise URLError(err)
urllib.error.URLError: <urlopen error [Errno 11001] getaddrinfo failed>
ERROR:root:Error for link http://server1.uralca.ru/download/uralca-qualified06-2018.crl
Traceback (most recent call last):
  File "C:\Users\a.karpihin\AppData\Local\Programs\Python\Python39\lib\urllib\request.py", line 1346, in do_open
    h.request(req.get_method(), req.selector, req.data, headers,
  File "C:\Users\a.karpihin\AppData\Local\Programs\Python\Python39\lib\http\client.py", line 1253, in request
    self._send_request(method, url, body, headers, encode_chunked)
  File "C:\Users\a.karpihin\AppData\Local\Programs\Python\Python39\lib\http\client.py", line 1299, in _send_request
    self.endheaders(body, encode_chunked=encode_chunked)
  File "C:\Users\a.karpihin\AppData\Local\Programs\Python\Python39\lib\http\client.py", line 1248, in endheaders
    self._send_output(message_body, encode_chunked=encode_chunked)
  File "C:\Users\a.karpihin\AppData\Local\Programs\Python\Python39\lib\http\client.py", line 1008, in _send_output
    self.send(msg)
  File "C:\Users\a.karpihin\AppData\Local\Programs\Python\Python39\lib\http\client.py", line 948, in send
    self.connect()
  File "C:\Users\a.karpihin\AppData\Local\Programs\Python\Python39\lib\http\client.py", line 919, in connect
    self.sock = self._create_connection(
  File "C:\Users\a.karpihin\AppData\Local\Programs\Python\Python39\lib\socket.py", line 843, in create_connection
    raise err
  File "C:\Users\a.karpihin\AppData\Local\Programs\Python\Python39\lib\socket.py", line 831, in create_connection
    sock.connect(sa)
TimeoutError: [WinError 10060] Попытка установить соединение была безуспешной, т.к. от другого компьютера за требуемое время не получен нужный отклик, или было разорвано уже установленное соединение из-за неверного отклика уже подключенного компьютера

During handling of the above exception, another exception occurred:

Traceback (most recent call last):
  File "C:\Users\a.karpihin\PycharmProjects\xml_perser\main.py", line 45, in <module>
    urlreq.urlretrieve(url_link.text, 'C:/Users/a.karpihin/Desktop/certs/отозванные/' + new_name + '.crl')
  File "C:\Users\a.karpihin\AppData\Local\Programs\Python\Python39\lib\urllib\request.py", line 239, in urlretrieve
    with contextlib.closing(urlopen(url, data)) as fp:
  File "C:\Users\a.karpihin\AppData\Local\Programs\Python\Python39\lib\urllib\request.py", line 214, in urlopen
    return opener.open(url, data, timeout)
  File "C:\Users\a.karpihin\AppData\Local\Programs\Python\Python39\lib\urllib\request.py", line 517, in open
    response = self._open(req, data)
  File "C:\Users\a.karpihin\AppData\Local\Programs\Python\Python39\lib\urllib\request.py", line 534, in _open
    result = self._call_chain(self.handle_open, protocol, protocol +
  File "C:\Users\a.karpihin\AppData\Local\Programs\Python\Python39\lib\urllib\request.py", line 494, in _call_chain
    result = func(*args)
  File "C:\Users\a.karpihin\AppData\Local\Programs\Python\Python39\lib\urllib\request.py", line 1375, in http_open
    return self.do_open(http.client.HTTPConnection, req)
  File "C:\Users\a.karpihin\AppData\Local\Programs\Python\Python39\lib\urllib\request.py", line 1349, in do_open
    raise URLError(err)
urllib.error.URLError: <urlopen error [WinError 10060] Попытка установить соединение была безуспешной, т.к. от другого компьютера за требуемое время не получен нужный отклик, или было разорвано уже установленное соединение из-за неверного отклика уже подключенного компьютера>
ERROR:root:Error for link http://rosteck.ru/storage/files/crl/89645c50b7c4cba6d22aaed722a7222ccc86e725.crl
Traceback (most recent call last):
  File "C:\Users\a.karpihin\PycharmProjects\xml_perser\main.py", line 45, in <module>
    urlreq.urlretrieve(url_link.text, 'C:/Users/a.karpihin/Desktop/certs/отозванные/' + new_name + '.crl')
  File "C:\Users\a.karpihin\AppData\Local\Programs\Python\Python39\lib\urllib\request.py", line 239, in urlretrieve
    with contextlib.closing(urlopen(url, data)) as fp:
  File "C:\Users\a.karpihin\AppData\Local\Programs\Python\Python39\lib\urllib\request.py", line 214, in urlopen
    return opener.open(url, data, timeout)
  File "C:\Users\a.karpihin\AppData\Local\Programs\Python\Python39\lib\urllib\request.py", line 517, in open
    response = self._open(req, data)
  File "C:\Users\a.karpihin\AppData\Local\Programs\Python\Python39\lib\urllib\request.py", line 534, in _open
    result = self._call_chain(self.handle_open, protocol, protocol +
  File "C:\Users\a.karpihin\AppData\Local\Programs\Python\Python39\lib\urllib\request.py", line 494, in _call_chain
    result = func(*args)
  File "C:\Users\a.karpihin\AppData\Local\Programs\Python\Python39\lib\urllib\request.py", line 1375, in http_open
    return self.do_open(http.client.HTTPConnection, req)
  File "C:\Users\a.karpihin\AppData\Local\Programs\Python\Python39\lib\urllib\request.py", line 1350, in do_open
    r = h.getresponse()
  File "C:\Users\a.karpihin\AppData\Local\Programs\Python\Python39\lib\http\client.py", line 1345, in getresponse
    response.begin()
  File "C:\Users\a.karpihin\AppData\Local\Programs\Python\Python39\lib\http\client.py", line 307, in begin
    version, status, reason = self._read_status()
  File "C:\Users\a.karpihin\AppData\Local\Programs\Python\Python39\lib\http\client.py", line 268, in _read_status
    line = str(self.fp.readline(_MAXLINE + 1), "iso-8859-1")
  File "C:\Users\a.karpihin\AppData\Local\Programs\Python\Python39\lib\socket.py", line 704, in readinto
    return self._sock.recv_into(b)
ConnectionResetError: [WinError 10054] Удаленный хост принудительно разорвал существующее подключение
ERROR:root:Error for link http://uc.fssp.gov.ru/files/udostov/8c93865786bd780c76fd89856c76f3679a68831d.crl
Traceback (most recent call last):
  File "C:\Users\a.karpihin\PycharmProjects\xml_perser\main.py", line 45, in <module>
    urlreq.urlretrieve(url_link.text, 'C:/Users/a.karpihin/Desktop/certs/отозванные/' + new_name + '.crl')
  File "C:\Users\a.karpihin\AppData\Local\Programs\Python\Python39\lib\urllib\request.py", line 239, in urlretrieve
    with contextlib.closing(urlopen(url, data)) as fp:
  File "C:\Users\a.karpihin\AppData\Local\Programs\Python\Python39\lib\urllib\request.py", line 214, in urlopen
    return opener.open(url, data, timeout)
  File "C:\Users\a.karpihin\AppData\Local\Programs\Python\Python39\lib\urllib\request.py", line 523, in open
    response = meth(req, response)
  File "C:\Users\a.karpihin\AppData\Local\Programs\Python\Python39\lib\urllib\request.py", line 632, in http_response
    response = self.parent.error(
  File "C:\Users\a.karpihin\AppData\Local\Programs\Python\Python39\lib\urllib\request.py", line 555, in error
    result = self._call_chain(*args)
  File "C:\Users\a.karpihin\AppData\Local\Programs\Python\Python39\lib\urllib\request.py", line 494, in _call_chain
    result = func(*args)
  File "C:\Users\a.karpihin\AppData\Local\Programs\Python\Python39\lib\urllib\request.py", line 747, in http_error_302
    return self.parent.open(new, timeout=req.timeout)
  File "C:\Users\a.karpihin\AppData\Local\Programs\Python\Python39\lib\urllib\request.py", line 523, in open
    response = meth(req, response)
  File "C:\Users\a.karpihin\AppData\Local\Programs\Python\Python39\lib\urllib\request.py", line 632, in http_response
    response = self.parent.error(
  File "C:\Users\a.karpihin\AppData\Local\Programs\Python\Python39\lib\urllib\request.py", line 561, in error
    return self._call_chain(*args)
  File "C:\Users\a.karpihin\AppData\Local\Programs\Python\Python39\lib\urllib\request.py", line 494, in _call_chain
    result = func(*args)
  File "C:\Users\a.karpihin\AppData\Local\Programs\Python\Python39\lib\urllib\request.py", line 641, in http_error_default
    raise HTTPError(req.full_url, code, msg, hdrs, fp)
urllib.error.HTTPError: HTTP Error 403: Forbidden
ERROR:root:Error for link http://ca.csr43.ru/files/2017/0A4D_rem.crl
Traceback (most recent call last):
  File "C:\Users\a.karpihin\AppData\Local\Programs\Python\Python39\lib\urllib\request.py", line 1346, in do_open
    h.request(req.get_method(), req.selector, req.data, headers,
  File "C:\Users\a.karpihin\AppData\Local\Programs\Python\Python39\lib\http\client.py", line 1253, in request
    self._send_request(method, url, body, headers, encode_chunked)
  File "C:\Users\a.karpihin\AppData\Local\Programs\Python\Python39\lib\http\client.py", line 1299, in _send_request
    self.endheaders(body, encode_chunked=encode_chunked)
  File "C:\Users\a.karpihin\AppData\Local\Programs\Python\Python39\lib\http\client.py", line 1248, in endheaders
    self._send_output(message_body, encode_chunked=encode_chunked)
  File "C:\Users\a.karpihin\AppData\Local\Programs\Python\Python39\lib\http\client.py", line 1008, in _send_output
    self.send(msg)
  File "C:\Users\a.karpihin\AppData\Local\Programs\Python\Python39\lib\http\client.py", line 948, in send
    self.connect()
  File "C:\Users\a.karpihin\AppData\Local\Programs\Python\Python39\lib\http\client.py", line 1422, in connect
    self.sock = self._context.wrap_socket(self.sock,
  File "C:\Users\a.karpihin\AppData\Local\Programs\Python\Python39\lib\ssl.py", line 500, in wrap_socket
    return self.sslsocket_class._create(
  File "C:\Users\a.karpihin\AppData\Local\Programs\Python\Python39\lib\ssl.py", line 1040, in _create
    self.do_handshake()
  File "C:\Users\a.karpihin\AppData\Local\Programs\Python\Python39\lib\ssl.py", line 1309, in do_handshake
    self._sslobj.do_handshake()
ssl.SSLCertVerificationError: [SSL: CERTIFICATE_VERIFY_FAILED] certificate verify failed: Hostname mismatch, certificate is not valid for 'ca.csr43.ru'. (_ssl.c:1129)

During handling of the above exception, another exception occurred:

Traceback (most recent call last):
  File "C:\Users\a.karpihin\PycharmProjects\xml_perser\main.py", line 45, in <module>
    urlreq.urlretrieve(url_link.text, 'C:/Users/a.karpihin/Desktop/certs/отозванные/' + new_name + '.crl')
  File "C:\Users\a.karpihin\AppData\Local\Programs\Python\Python39\lib\urllib\request.py", line 239, in urlretrieve
    with contextlib.closing(urlopen(url, data)) as fp:
  File "C:\Users\a.karpihin\AppData\Local\Programs\Python\Python39\lib\urllib\request.py", line 214, in urlopen
    return opener.open(url, data, timeout)
  File "C:\Users\a.karpihin\AppData\Local\Programs\Python\Python39\lib\urllib\request.py", line 523, in open
    response = meth(req, response)
  File "C:\Users\a.karpihin\AppData\Local\Programs\Python\Python39\lib\urllib\request.py", line 632, in http_response
    response = self.parent.error(
  File "C:\Users\a.karpihin\AppData\Local\Programs\Python\Python39\lib\urllib\request.py", line 555, in error
    result = self._call_chain(*args)
  File "C:\Users\a.karpihin\AppData\Local\Programs\Python\Python39\lib\urllib\request.py", line 494, in _call_chain
    result = func(*args)
  File "C:\Users\a.karpihin\AppData\Local\Programs\Python\Python39\lib\urllib\request.py", line 747, in http_error_302
    return self.parent.open(new, timeout=req.timeout)
  File "C:\Users\a.karpihin\AppData\Local\Programs\Python\Python39\lib\urllib\request.py", line 517, in open
    response = self._open(req, data)
  File "C:\Users\a.karpihin\AppData\Local\Programs\Python\Python39\lib\urllib\request.py", line 534, in _open
    result = self._call_chain(self.handle_open, protocol, protocol +
  File "C:\Users\a.karpihin\AppData\Local\Programs\Python\Python39\lib\urllib\request.py", line 494, in _call_chain
    result = func(*args)
  File "C:\Users\a.karpihin\AppData\Local\Programs\Python\Python39\lib\urllib\request.py", line 1389, in https_open
    return self.do_open(http.client.HTTPSConnection, req,
  File "C:\Users\a.karpihin\AppData\Local\Programs\Python\Python39\lib\urllib\request.py", line 1349, in do_open
    raise URLError(err)
urllib.error.URLError: <urlopen error [SSL: CERTIFICATE_VERIFY_FAILED] certificate verify failed: Hostname mismatch, certificate is not valid for 'ca.csr43.ru'. (_ssl.c:1129)>
ERROR:root:Error for link http://crl.squaretrade.ru/squaretrade2020.crl
Traceback (most recent call last):
  File "C:\Users\a.karpihin\PycharmProjects\xml_perser\main.py", line 45, in <module>
    urlreq.urlretrieve(url_link.text, 'C:/Users/a.karpihin/Desktop/certs/отозванные/' + new_name + '.crl')
  File "C:\Users\a.karpihin\AppData\Local\Programs\Python\Python39\lib\urllib\request.py", line 239, in urlretrieve
    with contextlib.closing(urlopen(url, data)) as fp:
  File "C:\Users\a.karpihin\AppData\Local\Programs\Python\Python39\lib\urllib\request.py", line 214, in urlopen
    return opener.open(url, data, timeout)
  File "C:\Users\a.karpihin\AppData\Local\Programs\Python\Python39\lib\urllib\request.py", line 523, in open
    response = meth(req, response)
  File "C:\Users\a.karpihin\AppData\Local\Programs\Python\Python39\lib\urllib\request.py", line 632, in http_response
    response = self.parent.error(
  File "C:\Users\a.karpihin\AppData\Local\Programs\Python\Python39\lib\urllib\request.py", line 561, in error
    return self._call_chain(*args)
  File "C:\Users\a.karpihin\AppData\Local\Programs\Python\Python39\lib\urllib\request.py", line 494, in _call_chain
    result = func(*args)
  File "C:\Users\a.karpihin\AppData\Local\Programs\Python\Python39\lib\urllib\request.py", line 641, in http_error_default
    raise HTTPError(req.full_url, code, msg, hdrs, fp)
urllib.error.HTTPError: HTTP Error 404: Not Found
ERROR:root:Error for link http://informtorgservis.ru/ca/cert/0C23_rem.crl
Traceback (most recent call last):
  File "C:\Users\a.karpihin\PycharmProjects\xml_perser\main.py", line 45, in <module>
    urlreq.urlretrieve(url_link.text, 'C:/Users/a.karpihin/Desktop/certs/отозванные/' + new_name + '.crl')
  File "C:\Users\a.karpihin\AppData\Local\Programs\Python\Python39\lib\urllib\request.py", line 239, in urlretrieve
    with contextlib.closing(urlopen(url, data)) as fp:
  File "C:\Users\a.karpihin\AppData\Local\Programs\Python\Python39\lib\urllib\request.py", line 214, in urlopen
    return opener.open(url, data, timeout)
  File "C:\Users\a.karpihin\AppData\Local\Programs\Python\Python39\lib\urllib\request.py", line 523, in open
    response = meth(req, response)
  File "C:\Users\a.karpihin\AppData\Local\Programs\Python\Python39\lib\urllib\request.py", line 632, in http_response
    response = self.parent.error(
  File "C:\Users\a.karpihin\AppData\Local\Programs\Python\Python39\lib\urllib\request.py", line 561, in error
    return self._call_chain(*args)
  File "C:\Users\a.karpihin\AppData\Local\Programs\Python\Python39\lib\urllib\request.py", line 494, in _call_chain
    result = func(*args)
  File "C:\Users\a.karpihin\AppData\Local\Programs\Python\Python39\lib\urllib\request.py", line 641, in http_error_default
    raise HTTPError(req.full_url, code, msg, hdrs, fp)
urllib.error.HTTPError: HTTP Error 403: Forbidden
ERROR:root:Error for link http://ra.cislink.com/ra/cdp/bfc42f181f343f18f4fd74296965f3891d370c55.crl
Traceback (most recent call last):
  File "C:\Users\a.karpihin\AppData\Local\Programs\Python\Python39\lib\urllib\request.py", line 1346, in do_open
    h.request(req.get_method(), req.selector, req.data, headers,
  File "C:\Users\a.karpihin\AppData\Local\Programs\Python\Python39\lib\http\client.py", line 1253, in request
    self._send_request(method, url, body, headers, encode_chunked)
  File "C:\Users\a.karpihin\AppData\Local\Programs\Python\Python39\lib\http\client.py", line 1299, in _send_request
    self.endheaders(body, encode_chunked=encode_chunked)
  File "C:\Users\a.karpihin\AppData\Local\Programs\Python\Python39\lib\http\client.py", line 1248, in endheaders
    self._send_output(message_body, encode_chunked=encode_chunked)
  File "C:\Users\a.karpihin\AppData\Local\Programs\Python\Python39\lib\http\client.py", line 1008, in _send_output
    self.send(msg)
  File "C:\Users\a.karpihin\AppData\Local\Programs\Python\Python39\lib\http\client.py", line 948, in send
    self.connect()
  File "C:\Users\a.karpihin\AppData\Local\Programs\Python\Python39\lib\http\client.py", line 919, in connect
    self.sock = self._create_connection(
  File "C:\Users\a.karpihin\AppData\Local\Programs\Python\Python39\lib\socket.py", line 843, in create_connection
    raise err
  File "C:\Users\a.karpihin\AppData\Local\Programs\Python\Python39\lib\socket.py", line 831, in create_connection
    sock.connect(sa)
TimeoutError: [WinError 10060] Попытка установить соединение была безуспешной, т.к. от другого компьютера за требуемое время не получен нужный отклик, или было разорвано уже установленное соединение из-за неверного отклика уже подключенного компьютера

During handling of the above exception, another exception occurred:

Traceback (most recent call last):
  File "C:\Users\a.karpihin\PycharmProjects\xml_perser\main.py", line 45, in <module>
    urlreq.urlretrieve(url_link.text, 'C:/Users/a.karpihin/Desktop/certs/отозванные/' + new_name + '.crl')
  File "C:\Users\a.karpihin\AppData\Local\Programs\Python\Python39\lib\urllib\request.py", line 239, in urlretrieve
    with contextlib.closing(urlopen(url, data)) as fp:
  File "C:\Users\a.karpihin\AppData\Local\Programs\Python\Python39\lib\urllib\request.py", line 214, in urlopen
    return opener.open(url, data, timeout)
  File "C:\Users\a.karpihin\AppData\Local\Programs\Python\Python39\lib\urllib\request.py", line 517, in open
    response = self._open(req, data)
  File "C:\Users\a.karpihin\AppData\Local\Programs\Python\Python39\lib\urllib\request.py", line 534, in _open
    result = self._call_chain(self.handle_open, protocol, protocol +
  File "C:\Users\a.karpihin\AppData\Local\Programs\Python\Python39\lib\urllib\request.py", line 494, in _call_chain
    result = func(*args)
  File "C:\Users\a.karpihin\AppData\Local\Programs\Python\Python39\lib\urllib\request.py", line 1375, in http_open
    return self.do_open(http.client.HTTPConnection, req)
  File "C:\Users\a.karpihin\AppData\Local\Programs\Python\Python39\lib\urllib\request.py", line 1349, in do_open
    raise URLError(err)
urllib.error.URLError: <urlopen error [WinError 10060] Попытка установить соединение была безуспешной, т.к. от другого компьютера за требуемое время не получен нужный отклик, или было разорвано уже установленное соединение из-за неверного отклика уже подключенного компьютера>
ERROR:root:Error for link http://cdp.dikeyca.ru/98c9a1d6d2dde9b64d58808790154cfb03f1c309.crl
Traceback (most recent call last):
  File "C:\Users\a.karpihin\AppData\Local\Programs\Python\Python39\lib\urllib\request.py", line 1346, in do_open
    h.request(req.get_method(), req.selector, req.data, headers,
  File "C:\Users\a.karpihin\AppData\Local\Programs\Python\Python39\lib\http\client.py", line 1253, in request
    self._send_request(method, url, body, headers, encode_chunked)
  File "C:\Users\a.karpihin\AppData\Local\Programs\Python\Python39\lib\http\client.py", line 1299, in _send_request
    self.endheaders(body, encode_chunked=encode_chunked)
  File "C:\Users\a.karpihin\AppData\Local\Programs\Python\Python39\lib\http\client.py", line 1248, in endheaders
    self._send_output(message_body, encode_chunked=encode_chunked)
  File "C:\Users\a.karpihin\AppData\Local\Programs\Python\Python39\lib\http\client.py", line 1008, in _send_output
    self.send(msg)
  File "C:\Users\a.karpihin\AppData\Local\Programs\Python\Python39\lib\http\client.py", line 948, in send
    self.connect()
  File "C:\Users\a.karpihin\AppData\Local\Programs\Python\Python39\lib\http\client.py", line 919, in connect
    self.sock = self._create_connection(
  File "C:\Users\a.karpihin\AppData\Local\Programs\Python\Python39\lib\socket.py", line 822, in create_connection
    for res in getaddrinfo(host, port, 0, SOCK_STREAM):
  File "C:\Users\a.karpihin\AppData\Local\Programs\Python\Python39\lib\socket.py", line 953, in getaddrinfo
    for res in _socket.getaddrinfo(host, port, family, type, proto, flags):
socket.gaierror: [Errno 11002] getaddrinfo failed

During handling of the above exception, another exception occurred:

Traceback (most recent call last):
  File "C:\Users\a.karpihin\PycharmProjects\xml_perser\main.py", line 45, in <module>
    urlreq.urlretrieve(url_link.text, 'C:/Users/a.karpihin/Desktop/certs/отозванные/' + new_name + '.crl')
  File "C:\Users\a.karpihin\AppData\Local\Programs\Python\Python39\lib\urllib\request.py", line 239, in urlretrieve
    with contextlib.closing(urlopen(url, data)) as fp:
  File "C:\Users\a.karpihin\AppData\Local\Programs\Python\Python39\lib\urllib\request.py", line 214, in urlopen
    return opener.open(url, data, timeout)
  File "C:\Users\a.karpihin\AppData\Local\Programs\Python\Python39\lib\urllib\request.py", line 517, in open
    response = self._open(req, data)
  File "C:\Users\a.karpihin\AppData\Local\Programs\Python\Python39\lib\urllib\request.py", line 534, in _open
    result = self._call_chain(self.handle_open, protocol, protocol +
  File "C:\Users\a.karpihin\AppData\Local\Programs\Python\Python39\lib\urllib\request.py", line 494, in _call_chain
    result = func(*args)
  File "C:\Users\a.karpihin\AppData\Local\Programs\Python\Python39\lib\urllib\request.py", line 1375, in http_open
    return self.do_open(http.client.HTTPConnection, req)
  File "C:\Users\a.karpihin\AppData\Local\Programs\Python\Python39\lib\urllib\request.py", line 1349, in do_open
    raise URLError(err)
urllib.error.URLError: <urlopen error [Errno 11002] getaddrinfo failed>
ERROR:root:Error for link http://www.fskn.ru/UC/CDP/root2014.crl
Traceback (most recent call last):
  File "C:\Users\a.karpihin\PycharmProjects\xml_perser\main.py", line 45, in <module>
    urlreq.urlretrieve(url_link.text, 'C:/Users/a.karpihin/Desktop/certs/отозванные/' + new_name + '.crl')
  File "C:\Users\a.karpihin\AppData\Local\Programs\Python\Python39\lib\urllib\request.py", line 239, in urlretrieve
    with contextlib.closing(urlopen(url, data)) as fp:
  File "C:\Users\a.karpihin\AppData\Local\Programs\Python\Python39\lib\urllib\request.py", line 214, in urlopen
    return opener.open(url, data, timeout)
  File "C:\Users\a.karpihin\AppData\Local\Programs\Python\Python39\lib\urllib\request.py", line 523, in open
    response = meth(req, response)
  File "C:\Users\a.karpihin\AppData\Local\Programs\Python\Python39\lib\urllib\request.py", line 632, in http_response
    response = self.parent.error(
  File "C:\Users\a.karpihin\AppData\Local\Programs\Python\Python39\lib\urllib\request.py", line 555, in error
    result = self._call_chain(*args)
  File "C:\Users\a.karpihin\AppData\Local\Programs\Python\Python39\lib\urllib\request.py", line 494, in _call_chain
    result = func(*args)
  File "C:\Users\a.karpihin\AppData\Local\Programs\Python\Python39\lib\urllib\request.py", line 747, in http_error_302
    return self.parent.open(new, timeout=req.timeout)
  File "C:\Users\a.karpihin\AppData\Local\Programs\Python\Python39\lib\urllib\request.py", line 523, in open
    response = meth(req, response)
  File "C:\Users\a.karpihin\AppData\Local\Programs\Python\Python39\lib\urllib\request.py", line 632, in http_response
    response = self.parent.error(
  File "C:\Users\a.karpihin\AppData\Local\Programs\Python\Python39\lib\urllib\request.py", line 555, in error
    result = self._call_chain(*args)
  File "C:\Users\a.karpihin\AppData\Local\Programs\Python\Python39\lib\urllib\request.py", line 494, in _call_chain
    result = func(*args)
  File "C:\Users\a.karpihin\AppData\Local\Programs\Python\Python39\lib\urllib\request.py", line 747, in http_error_302
    return self.parent.open(new, timeout=req.timeout)
  File "C:\Users\a.karpihin\AppData\Local\Programs\Python\Python39\lib\urllib\request.py", line 523, in open
    response = meth(req, response)
  File "C:\Users\a.karpihin\AppData\Local\Programs\Python\Python39\lib\urllib\request.py", line 632, in http_response
    response = self.parent.error(
  File "C:\Users\a.karpihin\AppData\Local\Programs\Python\Python39\lib\urllib\request.py", line 561, in error
    return self._call_chain(*args)
  File "C:\Users\a.karpihin\AppData\Local\Programs\Python\Python39\lib\urllib\request.py", line 494, in _call_chain
    result = func(*args)
  File "C:\Users\a.karpihin\AppData\Local\Programs\Python\Python39\lib\urllib\request.py", line 641, in http_error_default
    raise HTTPError(req.full_url, code, msg, hdrs, fp)
urllib.error.HTTPError: HTTP Error 404: Not Found
ERROR:root:Error for link http://www.primorsky.ru/ca/cdp/primkrai%20ca.crl
Traceback (most recent call last):
  File "C:\Users\a.karpihin\PycharmProjects\xml_perser\main.py", line 45, in <module>
    urlreq.urlretrieve(url_link.text, 'C:/Users/a.karpihin/Desktop/certs/отозванные/' + new_name + '.crl')
  File "C:\Users\a.karpihin\AppData\Local\Programs\Python\Python39\lib\urllib\request.py", line 239, in urlretrieve
    with contextlib.closing(urlopen(url, data)) as fp:
  File "C:\Users\a.karpihin\AppData\Local\Programs\Python\Python39\lib\urllib\request.py", line 214, in urlopen
    return opener.open(url, data, timeout)
  File "C:\Users\a.karpihin\AppData\Local\Programs\Python\Python39\lib\urllib\request.py", line 523, in open
    response = meth(req, response)
  File "C:\Users\a.karpihin\AppData\Local\Programs\Python\Python39\lib\urllib\request.py", line 632, in http_response
    response = self.parent.error(
  File "C:\Users\a.karpihin\AppData\Local\Programs\Python\Python39\lib\urllib\request.py", line 555, in error
    result = self._call_chain(*args)
  File "C:\Users\a.karpihin\AppData\Local\Programs\Python\Python39\lib\urllib\request.py", line 494, in _call_chain
    result = func(*args)
  File "C:\Users\a.karpihin\AppData\Local\Programs\Python\Python39\lib\urllib\request.py", line 747, in http_error_302
    return self.parent.open(new, timeout=req.timeout)
  File "C:\Users\a.karpihin\AppData\Local\Programs\Python\Python39\lib\urllib\request.py", line 523, in open
    response = meth(req, response)
  File "C:\Users\a.karpihin\AppData\Local\Programs\Python\Python39\lib\urllib\request.py", line 632, in http_response
    response = self.parent.error(
  File "C:\Users\a.karpihin\AppData\Local\Programs\Python\Python39\lib\urllib\request.py", line 561, in error
    return self._call_chain(*args)
  File "C:\Users\a.karpihin\AppData\Local\Programs\Python\Python39\lib\urllib\request.py", line 494, in _call_chain
    result = func(*args)
  File "C:\Users\a.karpihin\AppData\Local\Programs\Python\Python39\lib\urllib\request.py", line 641, in http_error_default
    raise HTTPError(req.full_url, code, msg, hdrs, fp)
urllib.error.HTTPError: HTTP Error 403: Forbidden
ERROR:root:Error for link http://adm44.ru/i/cert/3C5675861A5A0827D18F.crl
Traceback (most recent call last):
  File "C:\Users\a.karpihin\PycharmProjects\xml_perser\main.py", line 45, in <module>
    urlreq.urlretrieve(url_link.text, 'C:/Users/a.karpihin/Desktop/certs/отозванные/' + new_name + '.crl')
  File "C:\Users\a.karpihin\AppData\Local\Programs\Python\Python39\lib\urllib\request.py", line 239, in urlretrieve
    with contextlib.closing(urlopen(url, data)) as fp:
  File "C:\Users\a.karpihin\AppData\Local\Programs\Python\Python39\lib\urllib\request.py", line 214, in urlopen
    return opener.open(url, data, timeout)
  File "C:\Users\a.karpihin\AppData\Local\Programs\Python\Python39\lib\urllib\request.py", line 523, in open
    response = meth(req, response)
  File "C:\Users\a.karpihin\AppData\Local\Programs\Python\Python39\lib\urllib\request.py", line 632, in http_response
    response = self.parent.error(
  File "C:\Users\a.karpihin\AppData\Local\Programs\Python\Python39\lib\urllib\request.py", line 561, in error
    return self._call_chain(*args)
  File "C:\Users\a.karpihin\AppData\Local\Programs\Python\Python39\lib\urllib\request.py", line 494, in _call_chain
    result = func(*args)
  File "C:\Users\a.karpihin\AppData\Local\Programs\Python\Python39\lib\urllib\request.py", line 641, in http_error_default
    raise HTTPError(req.full_url, code, msg, hdrs, fp)
urllib.error.HTTPError: HTTP Error 403: Forbidden
ERROR:root:Error for link http://www.tbt32.ru/files/fdce8d158376d1515221f891812ff4d314b8df4b.crl
Traceback (most recent call last):
  File "C:\Users\a.karpihin\PycharmProjects\xml_perser\main.py", line 45, in <module>
    urlreq.urlretrieve(url_link.text, 'C:/Users/a.karpihin/Desktop/certs/отозванные/' + new_name + '.crl')
  File "C:\Users\a.karpihin\AppData\Local\Programs\Python\Python39\lib\urllib\request.py", line 239, in urlretrieve
    with contextlib.closing(urlopen(url, data)) as fp:
  File "C:\Users\a.karpihin\AppData\Local\Programs\Python\Python39\lib\urllib\request.py", line 214, in urlopen
    return opener.open(url, data, timeout)
  File "C:\Users\a.karpihin\AppData\Local\Programs\Python\Python39\lib\urllib\request.py", line 523, in open
    response = meth(req, response)
  File "C:\Users\a.karpihin\AppData\Local\Programs\Python\Python39\lib\urllib\request.py", line 632, in http_response
    response = self.parent.error(
  File "C:\Users\a.karpihin\AppData\Local\Programs\Python\Python39\lib\urllib\request.py", line 561, in error
    return self._call_chain(*args)
  File "C:\Users\a.karpihin\AppData\Local\Programs\Python\Python39\lib\urllib\request.py", line 494, in _call_chain
    result = func(*args)
  File "C:\Users\a.karpihin\AppData\Local\Programs\Python\Python39\lib\urllib\request.py", line 641, in http_error_default
    raise HTTPError(req.full_url, code, msg, hdrs, fp)
urllib.error.HTTPError: HTTP Error 404: Not Found
ERROR:root:Error for link http://esotel.ru/files/cert2/Esotel-Rustelcom.crl
Traceback (most recent call last):
  File "C:\Users\a.karpihin\PycharmProjects\xml_perser\main.py", line 45, in <module>
    urlreq.urlretrieve(url_link.text, 'C:/Users/a.karpihin/Desktop/certs/отозванные/' + new_name + '.crl')
  File "C:\Users\a.karpihin\AppData\Local\Programs\Python\Python39\lib\urllib\request.py", line 239, in urlretrieve
    with contextlib.closing(urlopen(url, data)) as fp:
  File "C:\Users\a.karpihin\AppData\Local\Programs\Python\Python39\lib\urllib\request.py", line 214, in urlopen
    return opener.open(url, data, timeout)
  File "C:\Users\a.karpihin\AppData\Local\Programs\Python\Python39\lib\urllib\request.py", line 523, in open
    response = meth(req, response)
  File "C:\Users\a.karpihin\AppData\Local\Programs\Python\Python39\lib\urllib\request.py", line 632, in http_response
    response = self.parent.error(
  File "C:\Users\a.karpihin\AppData\Local\Programs\Python\Python39\lib\urllib\request.py", line 561, in error
    return self._call_chain(*args)
  File "C:\Users\a.karpihin\AppData\Local\Programs\Python\Python39\lib\urllib\request.py", line 494, in _call_chain
    result = func(*args)
  File "C:\Users\a.karpihin\AppData\Local\Programs\Python\Python39\lib\urllib\request.py", line 641, in http_error_default
    raise HTTPError(req.full_url, code, msg, hdrs, fp)
urllib.error.HTTPError: HTTP Error 403: Forbidden
ERROR:root:Error for link http://uc.rosinv.ru/cdp/rti15.crl
Traceback (most recent call last):
  File "C:\Users\a.karpihin\AppData\Local\Programs\Python\Python39\lib\urllib\request.py", line 1346, in do_open
    h.request(req.get_method(), req.selector, req.data, headers,
  File "C:\Users\a.karpihin\AppData\Local\Programs\Python\Python39\lib\http\client.py", line 1253, in request
    self._send_request(method, url, body, headers, encode_chunked)
  File "C:\Users\a.karpihin\AppData\Local\Programs\Python\Python39\lib\http\client.py", line 1299, in _send_request
    self.endheaders(body, encode_chunked=encode_chunked)
  File "C:\Users\a.karpihin\AppData\Local\Programs\Python\Python39\lib\http\client.py", line 1248, in endheaders
    self._send_output(message_body, encode_chunked=encode_chunked)
  File "C:\Users\a.karpihin\AppData\Local\Programs\Python\Python39\lib\http\client.py", line 1008, in _send_output
    self.send(msg)
  File "C:\Users\a.karpihin\AppData\Local\Programs\Python\Python39\lib\http\client.py", line 948, in send
    self.connect()
  File "C:\Users\a.karpihin\AppData\Local\Programs\Python\Python39\lib\http\client.py", line 919, in connect
    self.sock = self._create_connection(
  File "C:\Users\a.karpihin\AppData\Local\Programs\Python\Python39\lib\socket.py", line 843, in create_connection
    raise err
  File "C:\Users\a.karpihin\AppData\Local\Programs\Python\Python39\lib\socket.py", line 831, in create_connection
    sock.connect(sa)
TimeoutError: [WinError 10060] Попытка установить соединение была безуспешной, т.к. от другого компьютера за требуемое время не получен нужный отклик, или было разорвано уже установленное соединение из-за неверного отклика уже подключенного компьютера

During handling of the above exception, another exception occurred:

Traceback (most recent call last):
  File "C:\Users\a.karpihin\PycharmProjects\xml_perser\main.py", line 45, in <module>
    urlreq.urlretrieve(url_link.text, 'C:/Users/a.karpihin/Desktop/certs/отозванные/' + new_name + '.crl')
  File "C:\Users\a.karpihin\AppData\Local\Programs\Python\Python39\lib\urllib\request.py", line 239, in urlretrieve
    with contextlib.closing(urlopen(url, data)) as fp:
  File "C:\Users\a.karpihin\AppData\Local\Programs\Python\Python39\lib\urllib\request.py", line 214, in urlopen
    return opener.open(url, data, timeout)
  File "C:\Users\a.karpihin\AppData\Local\Programs\Python\Python39\lib\urllib\request.py", line 517, in open
    response = self._open(req, data)
  File "C:\Users\a.karpihin\AppData\Local\Programs\Python\Python39\lib\urllib\request.py", line 534, in _open
    result = self._call_chain(self.handle_open, protocol, protocol +
  File "C:\Users\a.karpihin\AppData\Local\Programs\Python\Python39\lib\urllib\request.py", line 494, in _call_chain
    result = func(*args)
  File "C:\Users\a.karpihin\AppData\Local\Programs\Python\Python39\lib\urllib\request.py", line 1375, in http_open
    return self.do_open(http.client.HTTPConnection, req)
  File "C:\Users\a.karpihin\AppData\Local\Programs\Python\Python39\lib\urllib\request.py", line 1349, in do_open
    raise URLError(err)
urllib.error.URLError: <urlopen error [WinError 10060] Попытка установить соединение была безуспешной, т.к. от другого компьютера за требуемое время не получен нужный отклик, или было разорвано уже установленное соединение из-за неверного отклика уже подключенного компьютера>
ERROR:root:Error for link http://crl.rosneft.ru/public/5e921b3a122f7cfcdd71d7e52d9467558171f6ab.crl
Traceback (most recent call last):
  File "C:\Users\a.karpihin\PycharmProjects\xml_perser\main.py", line 45, in <module>
    urlreq.urlretrieve(url_link.text, 'C:/Users/a.karpihin/Desktop/certs/отозванные/' + new_name + '.crl')
  File "C:\Users\a.karpihin\AppData\Local\Programs\Python\Python39\lib\urllib\request.py", line 239, in urlretrieve
    with contextlib.closing(urlopen(url, data)) as fp:
  File "C:\Users\a.karpihin\AppData\Local\Programs\Python\Python39\lib\urllib\request.py", line 214, in urlopen
    return opener.open(url, data, timeout)
  File "C:\Users\a.karpihin\AppData\Local\Programs\Python\Python39\lib\urllib\request.py", line 523, in open
    response = meth(req, response)
  File "C:\Users\a.karpihin\AppData\Local\Programs\Python\Python39\lib\urllib\request.py", line 632, in http_response
    response = self.parent.error(
  File "C:\Users\a.karpihin\AppData\Local\Programs\Python\Python39\lib\urllib\request.py", line 561, in error
    return self._call_chain(*args)
  File "C:\Users\a.karpihin\AppData\Local\Programs\Python\Python39\lib\urllib\request.py", line 494, in _call_chain
    result = func(*args)
  File "C:\Users\a.karpihin\AppData\Local\Programs\Python\Python39\lib\urllib\request.py", line 641, in http_error_default
    raise HTTPError(req.full_url, code, msg, hdrs, fp)
urllib.error.HTTPError: HTTP Error 500: ( The specified network name is no longer available.  )
ERROR:root:Error for link http://ca.ecprf.ru/ra/cdp/acrl14.crl
Traceback (most recent call last):
  File "C:\Users\a.karpihin\AppData\Local\Programs\Python\Python39\lib\urllib\request.py", line 1346, in do_open
    h.request(req.get_method(), req.selector, req.data, headers,
  File "C:\Users\a.karpihin\AppData\Local\Programs\Python\Python39\lib\http\client.py", line 1253, in request
    self._send_request(method, url, body, headers, encode_chunked)
  File "C:\Users\a.karpihin\AppData\Local\Programs\Python\Python39\lib\http\client.py", line 1299, in _send_request
    self.endheaders(body, encode_chunked=encode_chunked)
  File "C:\Users\a.karpihin\AppData\Local\Programs\Python\Python39\lib\http\client.py", line 1248, in endheaders
    self._send_output(message_body, encode_chunked=encode_chunked)
  File "C:\Users\a.karpihin\AppData\Local\Programs\Python\Python39\lib\http\client.py", line 1008, in _send_output
    self.send(msg)
  File "C:\Users\a.karpihin\AppData\Local\Programs\Python\Python39\lib\http\client.py", line 948, in send
    self.connect()
  File "C:\Users\a.karpihin\AppData\Local\Programs\Python\Python39\lib\http\client.py", line 919, in connect
    self.sock = self._create_connection(
  File "C:\Users\a.karpihin\AppData\Local\Programs\Python\Python39\lib\socket.py", line 822, in create_connection
    for res in getaddrinfo(host, port, 0, SOCK_STREAM):
  File "C:\Users\a.karpihin\AppData\Local\Programs\Python\Python39\lib\socket.py", line 953, in getaddrinfo
    for res in _socket.getaddrinfo(host, port, family, type, proto, flags):
socket.gaierror: [Errno 11001] getaddrinfo failed

During handling of the above exception, another exception occurred:

Traceback (most recent call last):
  File "C:\Users\a.karpihin\PycharmProjects\xml_perser\main.py", line 45, in <module>
    urlreq.urlretrieve(url_link.text, 'C:/Users/a.karpihin/Desktop/certs/отозванные/' + new_name + '.crl')
  File "C:\Users\a.karpihin\AppData\Local\Programs\Python\Python39\lib\urllib\request.py", line 239, in urlretrieve
    with contextlib.closing(urlopen(url, data)) as fp:
  File "C:\Users\a.karpihin\AppData\Local\Programs\Python\Python39\lib\urllib\request.py", line 214, in urlopen
    return opener.open(url, data, timeout)
  File "C:\Users\a.karpihin\AppData\Local\Programs\Python\Python39\lib\urllib\request.py", line 517, in open
    response = self._open(req, data)
  File "C:\Users\a.karpihin\AppData\Local\Programs\Python\Python39\lib\urllib\request.py", line 534, in _open
    result = self._call_chain(self.handle_open, protocol, protocol +
  File "C:\Users\a.karpihin\AppData\Local\Programs\Python\Python39\lib\urllib\request.py", line 494, in _call_chain
    result = func(*args)
  File "C:\Users\a.karpihin\AppData\Local\Programs\Python\Python39\lib\urllib\request.py", line 1375, in http_open
    return self.do_open(http.client.HTTPConnection, req)
  File "C:\Users\a.karpihin\AppData\Local\Programs\Python\Python39\lib\urllib\request.py", line 1349, in do_open
    raise URLError(err)
urllib.error.URLError: <urlopen error [Errno 11001] getaddrinfo failed>
